Workbook
Name Cap_1: Inputs!$B$5
Name Cap_2: Inputs!$B$6
Name Cap_3: Inputs!$B$7
Name Cap_base: Inputs!$B$37
Name Capex: Inputs!$B$47
Name CapVec: Inputs!$B$5:$B$7
Name DaysYear: Inputs!$B$48
Name dt: Inputs!$B$51
Name E_nom: Inputs!$B$17
Name FC_E1: FuelCurves!$B$5:$B$8
Name FC_E2: FuelCurves!$C$5:$C$8
Name FC_E3: FuelCurves!$D$5:$D$8
Name FC_L: FuelCurves!$A$5:$A$8
Name GasCost: Inputs!$B$42
Name GridCost: Inputs!$B$44
Name Init1: Inputs!$B$12
Name Init2: Inputs!$B$13
Name Init3: Inputs!$B$14
Name MinOff: Inputs!$B$10
Name MinRun: Inputs!$B$9
Name MinStable: Inputs!$B$8
Name N_base: Inputs!$B$36
Name OMhour: Inputs!$B$45
Name P_aux: Inputs!$B$25
Name P_pcs: Inputs!$B$18
Name RTE: Inputs!$B$19
Name SOC_init: Inputs!$B$22
Name SOC_max: Inputs!$B$21
Name SOC_min: Inputs!$B$20
Name SOC_startT: Inputs!$B$30
Name SOC_stopT: Inputs!$B$31
Name StartEqH: Inputs!$B$46
Name StartMargin: Inputs!$B$32
Name StartRamp: Inputs!$B$11
Name StopMargin: Inputs!$B$33
Name TaperEnd: Inputs!$B$24
Name TaperStart: Inputs!$B$23

Sheet Read me
B2: CHP + BESS dispatch simulation — read me
B3: Built 21 Aug 2026. Synthetic data throughout; every number is a placeholder until the client's data arrives.
B5: What this model does
B6: Steps through one 24-hour day at 1-minute resolution and applies a fixed rule set to decide how many engines run.
B7: It is a forward simulation, not an optimisation. There is no solver and no forecast — deliberately, because a rule set
B8: that pays back without foresight is a far easier case to defend than one that assumes perfect knowledge.
B10: The dispatch rules
B11: START a unit when SOC < SOC start threshold OR site load > running capacity + start margin
B12: STOP a unit when SOC > SOC stop threshold AND site load <= capacity after shedding + stop margin
B13: Engines run at 100% whenever they run; the battery absorbs the entire mismatch, positive or negative.
B14: Stop margin must stay below start margin — that gap is the hysteresis that prevents start/stop chatter.
B15: Start margin = 2.5 (the PCS rating) is the aggressive setting: engines start only when the battery saturates.
... B48: Green = pulled from another sheet.

Sheet Inputs
A1: CHP + BESS dispatch simulation — INPUTS
A2: Every blue cell is a free variable. Change it and the whole model recalculates. Yellow = placeholder needing real client data.
A4: ENGINES
A5: Unit 1 — rated electrical output | B5: 1.2 | C5: MW | D5: MWM, nameplate. Replace with the exact model rating.
A6: Unit 2 — rated electrical output | B6: 1.1 | C6: MW | D6: Jenbacher #1.
A7: Unit 3 — rated electrical output | B7: 1.1 | C7: MW | D7: Jenbacher #2.
A8: Minimum stable load | B8: 0.5 | C8: frac of rated | D8: ASSUMPTION — confirm per engine. Bounds how low the baseline can go.
A9: Minimum run time | B9: 30 | C9: min | D9: Once started, a unit cannot stop before this.
A10: Minimum off time | B10: 15 | C10: min | D10: Once stopped, a unit cannot restart before this.
A11: Start ramp time (command to full load) | B11: 2 | C11: min | D11: Unit output ramps linearly over this period.
A12: Unit 1 running at t=0 | B12: 1 | C12: 36526 | D12: Initial condition.
A13: Unit 2 running at t=0 | B13: 1 | C13: 36526 | D13: Initial condition.
A14: Unit 3 running at t=0 | B14: 0 | C14: 36526 | D14: Initial condition.
A16: BESS
A17: Nominal energy | B17: 5.5 | C17: MWh | D17: Change this to size a different pack.
A18: PCS power rating | B18: 2.5 | C18: MW | D18: Charge and discharge limit.
A19: Round-trip efficiency | B19: 0.88 | C19: frac | D19: AC-to-AC. Applied as sqrt(RTE) each direction.
A20: SOC floor (usable) | B20: 0.1 | C20: frac | D20: Below this the battery stops discharging; grid takes over.
A21: SOC ceiling (usable) | B21: 0.95 | C21: frac | D21: Physical top of the usable window.
A22: SOC at t=0 | B22: 0.6 | C22: frac | D22: Initial condition.
A23: Charge taper — start SOC | B23: 0.85 | C23: frac | D23: Above this the charge power limit falls linearly.
A24: Charge taper — end SOC | B24: 1 | C24: frac | D24: Charge power reaches zero here.
A25: BESS auxiliary load (HVAC etc.) | B25: 0.015 | C25: MW | D25: ASSUMPTION — added to site load in the BESS case only.
A27: CONTROL RULES
A28: Start a unit when: SOC < SOC_start OR site load > running capacity + Start margin
A29: Stop a unit when: SOC > SOC_stop AND site load <= capacity after shedding + Stop margin
A30: SOC start threshold | B30: 0.3 | C30: frac | D30: Low-SOC trigger to bring a unit on.
A31: SOC stop threshold | B31: 0.85 | C31: frac | D31: High-SOC trigger to shed a unit. Keep at/below the taper start.
A32: Start margin | B32: 2.5 | C32: MW | D32: AGGRESSIVE = PCS rating (2.5): start only when the battery saturates. CONSERVATIVE = 0: start as soon as the fleet is exceeded.
A33: Stop margin | B33: 2 | C33: MW | D33: Must be < Start margin. The gap is the hysteresis that prevents chatter.
A35: BASELINE (current operation, no BESS)
A36: Units running continuously | B36: 3 | C36: count | D36: How they run today: all units on, sharing load. Set 1/2/3.
A37: Baseline installed capacity | B37: =IF(Inputs!$B$36>=3,Cap_1+Cap_2+Cap_3,IF(Inputs!$B$36=2,Cap_1+Cap_2,Cap_1)) -> 3.4 | C37: MW | D37: Derived from the unit count above.
A39: ECONOMICS
A40: Gas price | B40: 45000 | C40: KZT / 1000 m³ | D40: PLACEHOLDER — the single most important commercial input.
A41: Gas lower heating value | B41: 9.5 | C41: kWh / m³ | D41: Typical pipeline gas. Confirm from the supply contract.
A42: Gas cost per MWh of gas energy | B42: =Inputs!$B$40/Inputs!$B$41 -> 4736.8421 | C42: KZT / MWh(gas) | D42: Price per 1000 m³ divided by LHV: 1000 m³ at LHV kWh/m³ equals LHV MWh of gas energy.
A43: Grid import tariff | B43: 50 | C43: KZT / kWh | D43: PLACEHOLDER — use their actual industrial tariff.
A44: Grid import tariff | B44: =Inputs!$B$43*1000 -> 50000 | C44: KZT / MWh | D44: Unit conversion.
A45: O&M cost per engine running hour | B45: 9000 | C45: KZT / h | D45: PLACEHOLDER. ONLY counts as a saving if their contract is per-hour, not per-MWh.
...

Sheet FuelCurves
A1: Electrical efficiency vs. loading (LHV)
A2: PLACEHOLDER VALUES — replace each column with the manufacturer's part-load curve for that specific engine.
A4: Loading (frac) | B4: Unit 1 — MWM | C4: Unit 2 — Jenbacher | D4: Unit 3 — Jenbacher
A5: 0.25 | B5: 0.3 | C5: 0.295 | D5: 0.29 | F5: The model interpolates linearly between these four points.
A6: 0.5 | B6: 0.365 | C6: 0.36 | D6: 0.354 | F6: Unit 3 is set slightly below Unit 2 to represent an engine further from overhaul.
A7: 0.75 | B7: 0.405 | C7: 0.4 | D7: 0.393 | F7: Loading values must stay in ascending order, and the last must be 1.00.
A8: 1 | B8: 0.428 | C8: 0.422 | D8: 0.415

Sheet Sim
A1: t (min) | B1: Time | C1: Process load (MW) | D1: Site load (MW) | E1: SOC prev | F1: Cap prev (MW) | G1: StartScore U1 | H1: StartScore U2 | I1: StartScore U3 | J1: StopScore U1 | K1: StopScore U2 | L1: StopScore U3 | M1: Start pick | N1: Stop pick | O1: Stop pick cap | P1: Need start | Q1: Can stop | R1: Action | S1: U1 on | T1: U2 on | U1: U3 on | V1: U1 timer | W1: U2 timer | X1: U3 timer | Y1: U1 avail (MW) | Z1: U2 avail (MW) | AA1: U3 avail (MW) | AB1: Capacity (MW) | AC1: Surplus (MW) | AD1: Taper factor | AE1: Chg limit (MW) | AF1: Dis limit (MW) | AG1: Charge (MW) | AH1: Discharge (MW) | AI1: CHP output (MW) | AJ1: Grid import (MW) | AK1: Loading (frac) | AL1: Curve idx | AM1: Eff U1 | AN1: Eff U2 | AO1: Eff U3 | AP1: Gas (MWh) | AQ1: SOC | AR1: Start event
A2: 0 | B2: =A2/1440 -> 0 | C2: 1.172 | D2: =C2+P_aux -> 1.187 | E2: =SOC_init -> 0.6 | F2: =Init1*Cap_1+Init2*Cap_2+Init3*Cap_3 -> 2.3 | G2: 0 | H2: 0 | I2: 0 | J2: 0 | K2: 0 | L2: 0 | M2: 0 | N2: 0 | O2: 0 | P2: 0 | Q2: 0 | R2: 0 | S2: =Init1 -> 1 | T2: =Init2 -> 1 | U2: =Init3 -> 0 | V2: 999 | W2: 999 | X2: 999 | Y2: =S2*Cap_1*MIN(1,(V2+dt)/StartRamp) -> 1.2 | Z2: =T2*Cap_2*MIN(1,(W2+dt)/StartRamp) -> 1.1 | AA2: =U2*Cap_3*MIN(1,(X2+dt)/StartRamp) -> 0 | AB2: =SUM(Y2:AA2) -> 2.3 | AC2: =AB2-D2 -> 1.113 | AD2: =MEDIAN(0,(TaperEnd-E2)/(TaperEnd-TaperStart),1) -> 1 | AE2: =MIN(P_pcs*AD2,MAX(0,SOC_max-E2)*E_nom*60/dt/SQRT(RTE)) -> 2.5 | AF2: =MIN(P_pcs,MAX(0,E2-SOC_min)*E_nom*60/dt*SQRT(RTE)) -> 2.5 | AG2: =IF(AC2>0,MIN(AC2,AE2),0) -> 1.113 | AH2: =IF(AC2<0,MIN(-AC2,AF2),0) -> 0 | AI2: =IF(AC2>0,D2+AG2,AB2) -> 2.3 | AJ2: =MAX(0,D2-AI2-AH2) -> 0 | AK2: =IF(AB2>0,AI2/AB2,0) -> 1 | AL2: =IF(AB2=0,1,MIN(MATCH(MEDIAN(MinStable,AK2,1),FC_L,1),3)) -> 3 | AM2: =INDEX(FC_E1,$AL2)+(MEDIAN(MinStable,$AK2,1)-INDEX(FC_L,$AL2))*(INDEX(FC_E1,$AL2+1)-INDEX(FC_E1,$AL2))/(INDEX(FC_L,$AL2+1)-INDEX(FC_L,$AL2)) -> 0.428 | AN2: =INDEX(FC_E2,$AL2)+(MEDIAN(MinStable,$AK2,1)-INDEX(FC_L,$AL2))*(INDEX(FC_E2,$AL2+1)-INDEX(FC_E2,$AL2))/(INDEX(FC_L,$AL2+1)-INDEX(FC_L,$AL2)) -> 0.422 | AO2: =INDEX(FC_E3,$AL2)+(MEDIAN(MinStable,$AK2,1)-INDEX(FC_L,$AL2))*(INDEX(FC_E3,$AL2+1)-INDEX(FC_E3,$AL2))/(INDEX(FC_L,$AL2+1)-INDEX(FC_L,$AL2)) -> 0.415 | AP2: =(IF(S2=1,Y2*AK2/AM2,0)+IF(T2=1,Z2*AK2/AN2,0)+IF(U2=1,AA2*AK2/AO2,0))*dt/60 -> 0.09017289 | AQ2: =E2+(AG2*SQRT(RTE)-AH2/SQRT(RTE))*dt/60/E_nom -> 0.6031639 | AR2: =IF(R2=1,1,0) -> 0
A3: 1 | B3: =A3/1440 -> 0.00069444444 | C3: 1.1482 | D3: =C3+P_aux -> 1.1632 | E3: =AQ2 -> 0.6031639 | F3: =AB2 -> 2.3 | G3: =IF(AND(S2=0,V2>=MinOff),V2,-1) -> -1 | H3: =IF(AND(T2=0,W2>=MinOff),W2,-1) -> -1 | I3: =IF(AND(U2=0,X2>=MinOff),X2,-1) -> 999 | J3: =IF(AND(S2=1,V2>=MinRun),V2,-1) -> 999 | K3: =IF(AND(T2=1,W2>=MinRun),W2,-1) -> 999 | L3: =IF(AND(U2=1,X2>=MinRun),X2,-1) -> -1 | M3: =IF(MAX(G3:I3)<0,0,MATCH(MAX(G3:I3),G3:I3,0)) -> 3 | N3: =IF(MAX(J3:L3)<0,0,MATCH(MAX(J3:L3),J3:L3,0)) -> 1 | O3: =IF(N3=0,0,INDEX(CapVec,N3)) -> 1.2 | P3: =IF(OR(D3>F3+StartMargin,E3<SOC_startT),1,0) -> 0 | Q3: =IF(AND(E3>SOC_stopT,D3<=F3-O3+StopMargin),1,0) -> 0 | R3: =IF(AND(P3=1,M3>0),1,IF(AND(P3=0,Q3=1,N3>0),-1,0)) -> 0 | S3: =S2+IF(AND(R3=1,M3=1),1,0)-IF(AND(R3=-1,N3=1),1,0) -> 1 | T3: =T2+IF(AND(R3=1,M3=2),1,0)-IF(AND(R3=-1,N3=2),1,0) -> 1 | U3: =U2+IF(AND(R3=1,M3=3),1,0)-IF(AND(R3=-1,N3=3),1,0) -> 0 | V3: =IF(S3<>S2,0,V2+dt) -> 1000 | W3: =IF(T3<>T2,0,W2+dt) -> 1000 | X3: =IF(U3<>U2,0,X2+dt) -> 1000 | Y3: =S3*Cap_1*MIN(1,(V3+dt)/StartRamp) -> 1.2 | Z3: =T3*Cap_2*MIN(1,(W3+dt)/StartRamp) -> 1.1 | AA3: =U3*Cap_3*MIN(1,(X3+dt)/StartRamp) -> 0 | AB3: =SUM(Y3:AA3) -> 2.3 | AC3: =AB3-D3 -> 1.1368 | AD3: =MEDIAN(0,(TaperEnd-E3)/(TaperEnd-TaperStart),1) -> 1 | AE3: =MIN(P_pcs*AD3,MAX(0,SOC_max-E3)*E_nom*60/dt/SQRT(RTE)) -> 2.5 | AF3: =MIN(P_pcs,MAX(0,E3-SOC_min)*E_nom*60/dt*SQRT(RTE)) -> 2.5 | AG3: =IF(AC3>0,MIN(AC3,AE3),0) -> 1.1368 | AH3: =IF(AC3<0,MIN(-AC3,AF3),0) -> 0 | AI3: =IF(AC3>0,D3+AG3,AB3) -> 2.3 | AJ3: =MAX(0,D3-AI3-AH3) -> 0 | AK3: =IF(AB3>0,AI3/AB3,0) -> 1 | AL3: =IF(AB3=0,1,MIN(MATCH(MEDIAN(MinStable,AK3,1),FC_L,1),3)) -> 3 | AM3: =INDEX(FC_E1,$AL3)+(MEDIAN(MinStable,$AK3,1)-INDEX(FC_L,$AL3))*(INDEX(FC_E1,$AL3+1)-INDEX(FC_E1,$AL3))/(INDEX(FC_L,$AL3+1)-INDEX(FC_L,$AL3)) -> 0.428 | AN3: =INDEX(FC_E2,$AL3)+(MEDIAN(MinStable,$AK3,1)-INDEX(FC_L,$AL3))*(INDEX(FC_E2,$AL3+1)-INDEX(FC_E2,$AL3))/(INDEX(FC_L,$AL3+1)-INDEX(FC_L,$AL3)) -> 0.422 | AO3: =INDEX(FC_E3,$AL3)+(MEDIAN(MinStable,$AK3,1)-INDEX(FC_L,$AL3))*(INDEX(FC_E3,$AL3+1)-INDEX(FC_E3,$AL3))/(INDEX(FC_L,$AL3+1)-INDEX(FC_L,$AL3)) -> 0.415 | AP3: =(IF(S3=1,Y3*AK3/AM3,0)+IF(T3=1,Z3*AK3/AN3,0)+IF(U3=1,AA3*AK3/AO3,0))*dt/60 -> 0.09017289 | AQ3: =E3+(AG3*SQRT(RTE)-AH3/SQRT(RTE))*dt/60/E_nom -> 0.60639545 | AR3: =IF(R3=1,1,0) -> 0
A4: 2 | B4: =A4/1440 -> 0.0013888889 | C4: 1.1061 | D4: =C4+P_aux -> 1.1211 | E4: =AQ3 -> 0.60639545 | F4: =AB3 -> 2.3 | G4: =IF(AND(S3=0,V3>=MinOff),V3,-1) -> -1 | H4: =IF(AND(T3=0,W3>=MinOff),W3,-1) -> -1 | I4: =IF(AND(U3=0,X3>=MinOff),X3,-1) -> 1000 | J4: =IF(AND(S3=1,V3>=MinRun),V3,-1) -> 1000 | K4: =IF(AND(T3=1,W3>=MinRun),W3,-1) -> 1000 | L4: =IF(AND(U3=1,X3>=MinRun),X3,-1) -> -1 | M4: =IF(MAX(G4:I4)<0,0,MATCH(MAX(G4:I4),G4:I4,0)) -> 3 | N4: =IF(MAX(J4:L4)<0,0,MATCH(MAX(J4:L4),J4:L4,0)) -> 1 | O4: =IF(N4=0,0,INDEX(CapVec,N4)) -> 1.2 | P4: =IF(OR(D4>F4+StartMargin,E4<SOC_startT),1,0) -> 0 | Q4: =IF(AND(E4>SOC_stopT,D4<=F4-O4+StopMargin),1,0) -> 0 | R4: =IF(AND(P4=1,M4>0),1,IF(AND(P4=0,Q4=1,N4>0),-1,0)) -> 0 | S4: =S3+IF(AND(R4=1,M4=1),1,0)-IF(AND(R4=-1,N4=1),1,0) -> 1 | T4: =T3+IF(AND(R4=1,M4=2),1,0)-IF(AND(R4=-1,N4=2),1,0) -> 1 | U4: =U3+IF(AND(R4=1,M4=3),1,0)-IF(AND(R4=-1,N4=3),1,0) -> 0 | V4: =IF(S4<>S3,0,V3+dt) -> 1001 | W4: =IF(T4<>T3,0,W3+dt) -> 1001 | X4: =IF(U4<>U3,0,X3+dt) -> 1001 | Y4: =S4*Cap_1*MIN(1,(V4+dt)/StartRamp) -> 1.2 | Z4: =T4*Cap_2*MIN(1,(W4+dt)/StartRamp) -> 1.1 | AA4: =U4*Cap_3*MIN(1,(X4+dt)/StartRamp) -> 0 | AB4: =SUM(Y4:AA4) -> 2.3 | AC4: =AB4-D4 -> 1.1789 | AD4: =MEDIAN(0,(TaperEnd-E4)/(TaperEnd-TaperStart),1) -> 1 | AE4: =MIN(P_pcs*AD4,MAX(0,SOC_max-E4)*E_nom*60/dt/SQRT(RTE)) -> 2.5 | AF4: =MIN(P_pcs,MAX(0,E4-SOC_min)*E_nom*60/dt*SQRT(RTE)) -> 2.5 | AG4: =IF(AC4>0,MIN(AC4,AE4),0) -> 1.1789 | AH4: =IF(AC4<0,MIN(-AC4,AF4),0) -> 0 | AI4: =IF(AC4>0,D4+AG4,AB4) -> 2.3 | AJ4: =MAX(0,D4-AI4-AH4) -> 0 | AK4: =IF(AB4>0,AI4/AB4,0) -> 1 | AL4: =IF(AB4=0,1,MIN(MATCH(MEDIAN(MinStable,AK4,1),FC_L,1),3)) -> 3 | AM4: =INDEX(FC_E1,$AL4)+(MEDIAN(MinStable,$AK4,1)-INDEX(FC_L,$AL4))*(INDEX(FC_E1,$AL4+1)-INDEX(FC_E1,$AL4))/(INDEX(FC_L,$AL4+1)-INDEX(FC_L,$AL4)) -> 0.428 | AN4: =INDEX(FC_E2,$AL4)+(MEDIAN(MinStable,$AK4,1)-INDEX(FC_L,$AL4))*(INDEX(FC_E2,$AL4+1)-INDEX(FC_E2,$AL4))/(INDEX(FC_L,$AL4+1)-INDEX(FC_L,$AL4)) -> 0.422 | AO4: =INDEX(FC_E3,$AL4)+(MEDIAN(MinStable,$AK4,1)-INDEX(FC_L,$AL4))*(INDEX(FC_E3,$AL4+1)-INDEX(FC_E3,$AL4))/(INDEX(FC_L,$AL4+1)-INDEX(FC_L,$AL4)) -> 0.415 | AP4: =(IF(S4=1,Y4*AK4/AM4,0)+IF(T4=1,Z4*AK4/AN4,0)+IF(U4=1,AA4*AK4/AO4,0))*dt/60 -> 0.09017289 | AQ4: =E4+(AG4*SQRT(RTE)-AH4/SQRT(RTE))*dt/60/E_nom -> 0.60974668 | AR4: =IF(R4=1,1,0) -> 0
A5: 3 | B5: =A5/1440 -> 0.0020833333 | C5: 1.1643 | D5: =C5+P_aux -> 1.1793 | E5: =AQ4 -> 0.60974668 | F5: =AB4 -> 2.3 | G5: =IF(AND(S4=0,V4>=MinOff),V4,-1) -> -1 | H5: =IF(AND(T4=0,W4>=MinOff),W4,-1) -> -1 | I5: =IF(AND(U4=0,X4>=MinOff),X4,-1) -> 1001 | J5: =IF(AND(S4=1,V4>=MinRun),V4,-1) -> 1001 | K5: =IF(AND(T4=1,W4>=MinRun),W4,-1) -> 1001 | L5: =IF(AND(U4=1,X4>=MinRun),X4,-1) -> -1 | M5: =IF(MAX(G5:I5)<0,0,MATCH(MAX(G5:I5),G5:I5,0)) -> 3 | N5: =IF(MAX(J5:L5)<0,0,MATCH(MAX(J5:L5),J5:L5,0)) -> 1 | O5: =IF(N5=0,0,INDEX(CapVec,N5)) -> 1.2 | P5: =IF(OR(D5>F5+StartMargin,E5<SOC_startT),1,0) -> 0 | Q5: =IF(AND(E5>SOC_stopT,D5<=F5-O5+StopMargin),1,0) -> 0 | R5: =IF(AND(P5=1,M5>0),1,IF(AND(P5=0,Q5=1,N5>0),-1,0)) -> 0 | S5: =S4+IF(AND(R5=1,M5=1),1,0)-IF(AND(R5=-1,N5=1),1,0) -> 1 | T5: =T4+IF(AND(R5=1,M5=2),1,0)-IF(AND(R5=-1,N5=2),1,0) -> 1 | U5: =U4+IF(AND(R5=1,M5=3),1,0)-IF(AND(R5=-1,N5=3),1,0) -> 0 | V5: =IF(S5<>S4,0,V4+dt) -> 1002 | W5: =IF(T5<>T4,0,W4+dt) -> 1002 | X5: =IF(U5<>U4,0,X4+dt) -> 1002 | Y5: =S5*Cap_1*MIN(1,(V5+dt)/StartRamp) -> 1.2 | Z5: =T5*Cap_2*MIN(1,(W5+dt)/StartRamp) -> 1.1 | AA5: =U5*Cap_3*MIN(1,(X5+dt)/StartRamp) -> 0 | AB5: =SUM(Y5:AA5) -> 2.3 | AC5: =AB5-D5 -> 1.1207 | AD5: =MEDIAN(0,(TaperEnd-E5)/(TaperEnd-TaperStart),1) -> 1 | AE5: =MIN(P_pcs*AD5,MAX(0,SOC_max-E5)*E_nom*60/dt/SQRT(RTE)) -> 2.5 | AF5: =MIN(P_pcs,MAX(0,E5-SOC_min)*E_nom*60/dt*SQRT(RTE)) -> 2.5 | AG5: =IF(AC5>0,MIN(AC5,AE5),0) -> 1.1207 | AH5: =IF(AC5<0,MIN(-AC5,AF5),0) -> 0 | AI5: =IF(AC5>0,D5+AG5,AB5) -> 2.3 | AJ5: =MAX(0,D5-AI5-AH5) -> 0 | AK5: =IF(AB5>0,AI5/AB5,0) -> 1 | AL5: =IF(AB5=0,1,MIN(MATCH(MEDIAN(MinStable,AK5,1),FC_L,1),3)) -> 3 | AM5: =INDEX(FC_E1,$AL5)+(MEDIAN(MinStable,$AK5,1)-INDEX(FC_L,$AL5))*(INDEX(FC_E1,$AL5+1)-INDEX(FC_E1,$AL5))/(INDEX(FC_L,$AL5+1)-INDEX(FC_L,$AL5)) -> 0.428 | AN5: =INDEX(FC_E2,$AL5)+(MEDIAN(MinStable,$AK5,1)-INDEX(FC_L,$AL5))*(INDEX(FC_E2,$AL5+1)-INDEX(FC_E2,$AL5))/(INDEX(FC_L,$AL5+1)-INDEX(FC_L,$AL5)) -> 0.422 | AO5: =INDEX(FC_E3,$AL5)+(MEDIAN(MinStable,$AK5,1)-INDEX(FC_L,$AL5))*(INDEX(FC_E3,$AL5+1)-INDEX(FC_E3,$AL5))/(INDEX(FC_L,$AL5+1)-INDEX(FC_L,$AL5)) -> 0.415 | AP5: =(IF(S5=1,Y5*AK5/AM5,0)+IF(T5=1,Z5*AK5/AN5,0)+IF(U5=1,AA5*AK5/AO5,0))*dt/60 -> 0.09017289 | AQ5: =E5+(AG5*SQRT(RTE)-AH5/SQRT(RTE))*dt/60/E_nom -> 0.61293247 | AR5: =IF(R5=1,1,0) -> 0
A6: 4 | B6: =A6/1440 -> 0.0027777778 | C6: 1.1384 | D6: =C6+P_aux -> 1.1534 | E6: =AQ5 -> 0.61293247 | F6: =AB5 -> 2.3 | G6: =IF(AND(S5=0,V5>=MinOff),V5,-1) -> -1 | H6: =IF(AND(T5=0,W5>=MinOff),W5,-1) -> -1 | I6: =IF(AND(U5=0,X5>=MinOff),X5,-1) -> 1002 | J6: =IF(AND(S5=1,V5>=MinRun),V5,-1) -> 1002 | K6: =IF(AND(T5=1,W5>=MinRun),W5,-1) -> 1002 | L6: =IF(AND(U5=1,X5>=MinRun),X5,-1) -> -1 | M6: =IF(MAX(G6:I6)<0,0,MATCH(MAX(G6:I6),G6:I6,0)) -> 3 | N6: =IF(MAX(J6:L6)<0,0,MATCH(MAX(J6:L6),J6:L6,0)) -> 1 | O6: =IF(N6=0,0,INDEX(CapVec,N6)) -> 1.2 | P6: =IF(OR(D6>F6+StartMargin,E6<SOC_startT),1,0) -> 0 | Q6: =IF(AND(E6>SOC_stopT,D6<=F6-O6+StopMargin),1,0) -> 0 | R6: =IF(AND(P6=1,M6>0),1,IF(AND(P6=0,Q6=1,N6>0),-1,0)) -> 0 | S6: =S5+IF(AND(R6=1,M6=1),1,0)-IF(AND(R6=-1,N6=1),1,0) -> 1 | T6: =T5+IF(AND(R6=1,M6=2),1,0)-IF(AND(R6=-1,N6=2),1,0) -> 1 | U6: =U5+IF(AND(R6=1,M6=3),1,0)-IF(AND(R6=-1,N6=3),1,0) -> 0 | V6: =IF(S6<>S5,0,V5+dt) -> 1003 | W6: =IF(T6<>T5,0,W5+dt) -> 1003 | X6: =IF(U6<>U5,0,X5+dt) -> 1003 | Y6: =S6*Cap_1*MIN(1,(V6+dt)/StartRamp) -> 1.2 | Z6: =T6*Cap_2*MIN(1,(W6+dt)/StartRamp) -> 1.1 | AA6: =U6*Cap_3*MIN(1,(X6+dt)/StartRamp) -> 0 | AB6: =SUM(Y6:AA6) -> 2.3 | AC6: =AB6-D6 -> 1.1466 | AD6: =MEDIAN(0,(TaperEnd-E6)/(TaperEnd-TaperStart),1) -> 1 | AE6: =MIN(P_pcs*AD6,MAX(0,SOC_max-E6)*E_nom*60/dt/SQRT(RTE)) -> 2.5 | AF6: =MIN(P_pcs,MAX(0,E6-SOC_min)*E_nom*60/dt*SQRT(RTE)) -> 2.5 | AG6: =IF(AC6>0,MIN(AC6,AE6),0) -> 1.1466 | AH6: =IF(AC6<0,MIN(-AC6,AF6),0) -> 0 | AI6: =IF(AC6>0,D6+AG6,AB6) -> 2.3 | AJ6: =MAX(0,D6-AI6-AH6) -> 0 | AK6: =IF(AB6>0,AI6/AB6,0) -> 1 | AL6: =IF(AB6=0,1,MIN(MATCH(MEDIAN(MinStable,AK6,1),FC_L,1),3)) -> 3 | AM6: =INDEX(FC_E1,$AL6)+(MEDIAN(MinStable,$AK6,1)-INDEX(FC_L,$AL6))*(INDEX(FC_E1,$AL6+1)-INDEX(FC_E1,$AL6))/(INDEX(FC_L,$AL6+1)-INDEX(FC_L,$AL6)) -> 0.428 | AN6: =INDEX(FC_E2,$AL6)+(MEDIAN(MinStable,$AK6,1)-INDEX(FC_L,$AL6))*(INDEX(FC_E2,$AL6+1)-INDEX(FC_E2,$AL6))/(INDEX(FC_L,$AL6+1)-INDEX(FC_L,$AL6)) -> 0.422 | AO6: =INDEX(FC_E3,$AL6)+(MEDIAN(MinStable,$AK6,1)-INDEX(FC_L,$AL6))*(INDEX(FC_E3,$AL6+1)-INDEX(FC_E3,$AL6))/(INDEX(FC_L,$AL6+1)-INDEX(FC_L,$AL6)) -> 0.415 | AP6: =(IF(S6=1,Y6*AK6/AM6,0)+IF(T6=1,Z6*AK6/AN6,0)+IF(U6=1,AA6*AK6/AO6,0))*dt/60 -> 0.09017289 | AQ6: =E6+(AG6*SQRT(RTE)-AH6/SQRT(RTE))*dt/60/E_nom -> 0.61619188 | AR6: =IF(R6=1,1,0) -> 0
A7: 5 | B7: =A7/1440 -> 0.0034722222 | C7: 1.2374 | D7: =C7+P_aux -> 1.2524 | E7: =AQ6 -> 0.61619188 | F7: =AB6 -> 2.3 | G7: =IF(AND(S6=0,V6>=MinOff),V6,-1) -> -1 | H7: =IF(AND(T6=0,W6>=MinOff),W6,-1) -> -1 | I7: =IF(AND(U6=0,X6>=MinOff),X6,-1) -> 1003 | J7: =IF(AND(S6=1,V6>=MinRun),V6,-1) -> 1003 | K7: =IF(AND(T6=1,W6>=MinRun),W6,-1) -> 1003 | L7: =IF(AND(U6=1,X6>=MinRun),X6,-1) -> -1 | M7: =IF(MAX(G7:I7)<0,0,MATCH(MAX(G7:I7),G7:I7,0)) -> 3 | N7: =IF(MAX(J7:L7)<0,0,MATCH(MAX(J7:L7),J7:L7,0)) -> 1 | O7: =IF(N7=0,0,INDEX(CapVec,N7)) -> 1.2 | P7: =IF(OR(D7>F7+StartMargin,E7<SOC_startT),1,0) -> 0 | Q7: =IF(AND(E7>SOC_stopT,D7<=F7-O7+StopMargin),1,0) -> 0 | R7: =IF(AND(P7=1,M7>0),1,IF(AND(P7=0,Q7=1,N7>0),-1,0)) -> 0 | S7: =S6+IF(AND(R7=1,M7=1),1,0)-IF(AND(R7=-1,N7=1),1,0) -> 1 | T7: =T6+IF(AND(R7=1,M7=2),1,0)-IF(AND(R7=-1,N7=2),1,0) -> 1 | U7: =U6+IF(AND(R7=1,M7=3),1,0)-IF(AND(R7=-1,N7=3),1,0) -> 0 | V7: =IF(S7<>S6,0,V6+dt) -> 1004 | W7: =IF(T7<>T6,0,W6+dt) -> 1004 | X7: =IF(U7<>U6,0,X6+dt) -> 1004 | Y7: =S7*Cap_1*MIN(1,(V7+dt)/StartRamp) -> 1.2 | Z7: =T7*Cap_2*MIN(1,(W7+dt)/StartRamp) -> 1.1 | AA7: =U7*Cap_3*MIN(1,(X7+dt)/StartRamp) -> 0 | AB7: =SUM(Y7:AA7) -> 2.3 | AC7: =AB7-D7 -> 1.0476 | AD7: =MEDIAN(0,(TaperEnd-E7)/(TaperEnd-TaperStart),1) -> 1 | AE7: =MIN(P_pcs*AD7,MAX(0,SOC_max-E7)*E_nom*60/dt/SQRT(RTE)) -> 2.5 | AF7: =MIN(P_pcs,MAX(0,E7-SOC_min)*E_nom*60/dt*SQRT(RTE)) -> 2.5 | AG7: =IF(AC7>0,MIN(AC7,AE7),0) -> 1.0476 | AH7: =IF(AC7<0,MIN(-AC7,AF7),0) -> 0 | AI7: =IF(AC7>0,D7+AG7,AB7) -> 2.3 | AJ7: =MAX(0,D7-AI7-AH7) -> 0 | AK7: =IF(AB7>0,AI7/AB7,0) -> 1 | AL7: =IF(AB7=0,1,MIN(MATCH(MEDIAN(MinStable,AK7,1),FC_L,1),3)) -> 3 | AM7: =INDEX(FC_E1,$AL7)+(MEDIAN(MinStable,$AK7,1)-INDEX(FC_L,$AL7))*(INDEX(FC_E1,$AL7+1)-INDEX(FC_E1,$AL7))/(INDEX(FC_L,$AL7+1)-INDEX(FC_L,$AL7)) -> 0.428 | AN7: =INDEX(FC_E2,$AL7)+(MEDIAN(MinStable,$AK7,1)-INDEX(FC_L,$AL7))*(INDEX(FC_E2,$AL7+1)-INDEX(FC_E2,$AL7))/(INDEX(FC_L,$AL7+1)-INDEX(FC_L,$AL7)) -> 0.422 | AO7: =INDEX(FC_E3,$AL7)+(MEDIAN(MinStable,$AK7,1)-INDEX(FC_L,$AL7))*(INDEX(FC_E3,$AL7+1)-INDEX(FC_E3,$AL7))/(INDEX(FC_L,$AL7+1)-INDEX(FC_L,$AL7)) -> 0.415 | AP7: =(IF(S7=1,Y7*AK7/AM7,0)+IF(T7=1,Z7*AK7/AN7,0)+IF(U7=1,AA7*AK7/AO7,0))*dt/60 -> 0.09017289 | AQ7: =E7+(AG7*SQRT(RTE)-AH7/SQRT(RTE))*dt/60/E_nom -> 0.61916987 | AR7: =IF(R7=1,1,0) -> 0
A8: 6 | B8: =A8/1440 -> 0.0041666667 | C8: 1.2077 | D8: =C8+P_aux -> 1.2227 | E8: =AQ7 -> 0.61916987 | F8: =AB7 -> 2.3 | G8: =IF(AND(S7=0,V7>=MinOff),V7,-1) -> -1 | H8: =IF(AND(T7=0,W7>=MinOff),W7,-1) -> -1 | I8: =IF(AND(U7=0,X7>=MinOff),X7,-1) -> 1004 | J8: =IF(AND(S7=1,V7>=MinRun),V7,-1) -> 1004 | K8: =IF(AND(T7=1,W7>=MinRun),W7,-1) -> 1004 | L8: =IF(AND(U7=1,X7>=MinRun),X7,-1) -> -1 | M8: =IF(MAX(G8:I8)<0,0,MATCH(MAX(G8:I8),G8:I8,0)) -> 3 | N8: =IF(MAX(J8:L8)<0,0,MATCH(MAX(J8:L8),J8:L8,0)) -> 1 | O8: =IF(N8=0,0,INDEX(CapVec,N8)) -> 1.2 | P8: =IF(OR(D8>F8+StartMargin,E8<SOC_startT),1,0) -> 0 | Q8: =IF(AND(E8>SOC_stopT,D8<=F8-O8+StopMargin),1,0) -> 0 | R8: =IF(AND(P8=1,M8>0),1,IF(AND(P8=0,Q8=1,N8>0),-1,0)) -> 0 | S8: =S7+IF(AND(R8=1,M8=1),1,0)-IF(AND(R8=-1,N8=1),1,0) -> 1 | T8: =T7+IF(AND(R8=1,M8=2),1,0)-IF(AND(R8=-1,N8=2),1,0) -> 1 | U8: =U7+IF(AND(R8=1,M8=3),1,0)-IF(AND(R8=-1,N8=3),1,0) -> 0 | V8: =IF(S8<>S7,0,V7+dt) -> 1005 | W8: =IF(T8<>T7,0,W7+dt) -> 1005 | X8: =IF(U8<>U7,0,X7+dt) -> 1005 | Y8: =S8*Cap_1*MIN(1,(V8+dt)/StartRamp) -> 1.2 | Z8: =T8*Cap_2*MIN(1,(W8+dt)/StartRamp) -> 1.1 | AA8: =U8*Cap_3*MIN(1,(X8+dt)/StartRamp) -> 0 | AB8: =SUM(Y8:AA8) -> 2.3 | AC8: =AB8-D8 -> 1.0773 | AD8: =MEDIAN(0,(TaperEnd-E8)/(TaperEnd-TaperStart),1) -> 1 | AE8: =MIN(P_pcs*AD8,MAX(0,SOC_max-E8)*E_nom*60/dt/SQRT(RTE)) -> 2.5 | AF8: =MIN(P_pcs,MAX(0,E8-SOC_min)*E_nom*60/dt*SQRT(RTE)) -> 2.5 | AG8: =IF(AC8>0,MIN(AC8,AE8),0) -> 1.0773 | AH8: =IF(AC8<0,MIN(-AC8,AF8),0) -> 0 | AI8: =IF(AC8>0,D8+AG8,AB8) -> 2.3 | AJ8: =MAX(0,D8-AI8-AH8) -> 0 | AK8: =IF(AB8>0,AI8/AB8,0) -> 1 | AL8: =IF(AB8=0,1,MIN(MATCH(MEDIAN(MinStable,AK8,1),FC_L,1),3)) -> 3 | AM8: =INDEX(FC_E1,$AL8)+(MEDIAN(MinStable,$AK8,1)-INDEX(FC_L,$AL8))*(INDEX(FC_E1,$AL8+1)-INDEX(FC_E1,$AL8))/(INDEX(FC_L,$AL8+1)-INDEX(FC_L,$AL8)) -> 0.428 | AN8: =INDEX(FC_E2,$AL8)+(MEDIAN(MinStable,$AK8,1)-INDEX(FC_L,$AL8))*(INDEX(FC_E2,$AL8+1)-INDEX(FC_E2,$AL8))/(INDEX(FC_L,$AL8+1)-INDEX(FC_L,$AL8)) -> 0.422 | AO8: =INDEX(FC_E3,$AL8)+(MEDIAN(MinStable,$AK8,1)-INDEX(FC_L,$AL8))*(INDEX(FC_E3,$AL8+1)-INDEX(FC_E3,$AL8))/(INDEX(FC_L,$AL8+1)-INDEX(FC_L,$AL8)) -> 0.415 | AP8: =(IF(S8=1,Y8*AK8/AM8,0)+IF(T8=1,Z8*AK8/AN8,0)+IF(U8=1,AA8*AK8/AO8,0))*dt/60 -> 0.09017289 | AQ8: =E8+(AG8*SQRT(RTE)-AH8/SQRT(RTE))*dt/60/E_nom -> 0.62223229 | AR8: =IF(R8=1,1,0) -> 0
A9: 7 | B9: =A9/1440 -> 0.0048611111 | C9: 1.1476 | D9: =C9+P_aux -> 1.1626 | E9: =AQ8 -> 0.62223229 | F9: =AB8 -> 2.3 | G9: =IF(AND(S8=0,V8>=MinOff),V8,-1) -> -1 | H9: =IF(AND(T8=0,W8>=MinOff),W8,-1) -> -1 | I9: =IF(AND(U8=0,X8>=MinOff),X8,-1) -> 1005 | J9: =IF(AND(S8=1,V8>=MinRun),V8,-1) -> 1005 | K9: =IF(AND(T8=1,W8>=MinRun),W8,-1) -> 1005 | L9: =IF(AND(U8=1,X8>=MinRun),X8,-1) -> -1 | M9: =IF(MAX(G9:I9)<0,0,MATCH(MAX(G9:I9),G9:I9,0)) -> 3 | N9: =IF(MAX(J9:L9)<0,0,MATCH(MAX(J9:L9),J9:L9,0)) -> 1 | O9: =IF(N9=0,0,INDEX(CapVec,N9)) -> 1.2 | P9: =IF(OR(D9>F9+StartMargin,E9<SOC_startT),1,0) -> 0 | Q9: =IF(AND(E9>SOC_stopT,D9<=F9-O9+StopMargin),1,0) -> 0 | R9: =IF(AND(P9=1,M9>0),1,IF(AND(P9=0,Q9=1,N9>0),-1,0)) -> 0 | S9: =S8+IF(AND(R9=1,M9=1),1,0)-IF(AND(R9=-1,N9=1),1,0) -> 1 | T9: =T8+IF(AND(R9=1,M9=2),1,0)-IF(AND(R9=-1,N9=2),1,0) -> 1 | U9: =U8+IF(AND(R9=1,M9=3),1,0)-IF(AND(R9=-1,N9=3),1,0) -> 0 | V9: =IF(S9<>S8,0,V8+dt) -> 1006 | W9: =IF(T9<>T8,0,W8+dt) -> 1006 | X9: =IF(U9<>U8,0,X8+dt) -> 1006 | Y9: =S9*Cap_1*MIN(1,(V9+dt)/StartRamp) -> 1.2 | Z9: =T9*Cap_2*MIN(1,(W9+dt)/StartRamp) -> 1.1 | AA9: =U9*Cap_3*MIN(1,(X9+dt)/StartRamp) -> 0 | AB9: =SUM(Y9:AA9) -> 2.3 | AC9: =AB9-D9 -> 1.1374 | AD9: =MEDIAN(0,(TaperEnd-E9)/(TaperEnd-TaperStart),1) -> 1 | AE9: =MIN(P_pcs*AD9,MAX(0,SOC_max-E9)*E_nom*60/dt/SQRT(RTE)) -> 2.5 | AF9: =MIN(P_pcs,MAX(0,E9-SOC_min)*E_nom*60/dt*SQRT(RTE)) -> 2.5 | AG9: =IF(AC9>0,MIN(AC9,AE9),0) -> 1.1374 | AH9: =IF(AC9<0,MIN(-AC9,AF9),0) -> 0 | AI9: =IF(AC9>0,D9+AG9,AB9) -> 2.3 | AJ9: =MAX(0,D9-AI9-AH9) -> 0 | AK9: =IF(AB9>0,AI9/AB9,0) -> 1 | AL9: =IF(AB9=0,1,MIN(MATCH(MEDIAN(MinStable,AK9,1),FC_L,1),3)) -> 3 | AM9: =INDEX(FC_E1,$AL9)+(MEDIAN(MinStable,$AK9,1)-INDEX(FC_L,$AL9))*(INDEX(FC_E1,$AL9+1)-INDEX(FC_E1,$AL9))/(INDEX(FC_L,$AL9+1)-INDEX(FC_L,$AL9)) -> 0.428 | AN9: =INDEX(FC_E2,$AL9)+(MEDIAN(MinStable,$AK9,1)-INDEX(FC_L,$AL9))*(INDEX(FC_E2,$AL9+1)-INDEX(FC_E2,$AL9))/(INDEX(FC_L,$AL9+1)-INDEX(FC_L,$AL9)) -> 0.422 | AO9: =INDEX(FC_E3,$AL9)+(MEDIAN(MinStable,$AK9,1)-INDEX(FC_L,$AL9))*(INDEX(FC_E3,$AL9+1)-INDEX(FC_E3,$AL9))/(INDEX(FC_L,$AL9+1)-INDEX(FC_L,$AL9)) -> 0.415 | AP9: =(IF(S9=1,Y9*AK9/AM9,0)+IF(T9=1,Z9*AK9/AN9,0)+IF(U9=1,AA9*AK9/AO9,0))*dt/60 -> 0.09017289 | AQ9: =E9+(AG9*SQRT(RTE)-AH9/SQRT(RTE))*dt/60/E_nom -> 0.62546555 | AR9: =IF(R9=1,1,0) -> 0
A10: 8 | B10: =A10/1440 -> 0.0055555556 | C10: 1.094 | D10: =C10+P_aux -> 1.109 | E10: =AQ9 -> 0.62546555 | F10: =AB9 -> 2.3 | G10: =IF(AND(S9=0,V9>=MinOff),V9,-1) -> -1 | H10: =IF(AND(T9=0,W9>=MinOff),W9,-1) -> -1 | I10: =IF(AND(U9=0,X9>=MinOff),X9,-1) -> 1006 | J10: =IF(AND(S9=1,V9>=MinRun),V9,-1) -> 1006 | K10: =IF(AND(T9=1,W9>=MinRun),W9,-1) -> 1006 | L10: =IF(AND(U9=1,X9>=MinRun),X9,-1) -> -1 | M10: =IF(MAX(G10:I10)<0,0,MATCH(MAX(G10:I10),G10:I10,0)) -> 3 | N10: =IF(MAX(J10:L10)<0,0,MATCH(MAX(J10:L10),J10:L10,0)) -> 1 | O10: =IF(N10=0,0,INDEX(CapVec,N10)) -> 1.2 | P10: =IF(OR(D10>F10+StartMargin,E10<SOC_startT),1,0) -> 0 | Q10: =IF(AND(E10>SOC_stopT,D10<=F10-O10+StopMargin),1,0) -> 0 | R10: =IF(AND(P10=1,M10>0),1,IF(AND(P10=0,Q10=1,N10>0),-1,0)) -> 0 | S10: =S9+IF(AND(R10=1,M10=1),1,0)-IF(AND(R10=-1,N10=1),1,0) -> 1 | T10: =T9+IF(AND(R10=1,M10=2),1,0)-IF(AND(R10=-1,N10=2),1,0) -> 1 | U10: =U9+IF(AND(R10=1,M10=3),1,0)-IF(AND(R10=-1,N10=3),1,0) -> 0 | V10: =IF(S10<>S9,0,V9+dt) -> 1007 | W10: =IF(T10<>T9,0,W9+dt) -> 1007 | X10: =IF(U10<>U9,0,X9+dt) -> 1007 | Y10: =S10*Cap_1*MIN(1,(V10+dt)/StartRamp) -> 1.2 | Z10: =T10*Cap_2*MIN(1,(W10+dt)/StartRamp) -> 1.1 | AA10: =U10*Cap_3*MIN(1,(X10+dt)/StartRamp) -> 0 | AB10: =SUM(Y10:AA10) -> 2.3 | AC10: =AB10-D10 -> 1.191 | AD10: =MEDIAN(0,(TaperEnd-E10)/(TaperEnd-TaperStart),1) -> 1 | AE10: =MIN(P_pcs*AD10,MAX(0,SOC_max-E10)*E_nom*60/dt/SQRT(RTE)) -> 2.5 | AF10: =MIN(P_pcs,MAX(0,E10-SOC_min)*E_nom*60/dt*SQRT(RTE)) -> 2.5 | AG10: =IF(AC10>0,MIN(AC10,AE10),0) -> 1.191 | AH10: =IF(AC10<0,MIN(-AC10,AF10),0) -> 0 | AI10: =IF(AC10>0,D10+AG10,AB10) -> 2.3 | AJ10: =MAX(0,D10-AI10-AH10) -> 0 | AK10: =IF(AB10>0,AI10/AB10,0) -> 1 | AL10: =IF(AB10=0,1,MIN(MATCH(MEDIAN(MinStable,AK10,1),FC_L,1),3)) -> 3 | AM10: =INDEX(FC_E1,$AL10)+(MEDIAN(MinStable,$AK10,1)-INDEX(FC_L,$AL10))*(INDEX(FC_E1,$AL10+1)-INDEX(FC_E1,$AL10))/(INDEX(FC_L,$AL10+1)-INDEX(FC_L,$AL10)) -> 0.428 | AN10: =INDEX(FC_E2,$AL10)+(MEDIAN(MinStable,$AK10,1)-INDEX(FC_L,$AL10))*(INDEX(FC_E2,$AL10+1)-INDEX(FC_E2,$AL10))/(INDEX(FC_L,$AL10+1)-INDEX(FC_L,$AL10)) -> 0.422 | AO10: =INDEX(FC_E3,$AL10)+(MEDIAN(MinStable,$AK10,1)-INDEX(FC_L,$AL10))*(INDEX(FC_E3,$AL10+1)-INDEX(FC_E3,$AL10))/(INDEX(FC_L,$AL10+1)-INDEX(FC_L,$AL10)) -> 0.415 | AP10: =(IF(S10=1,Y10*AK10/AM10,0)+IF(T10=1,Z10*AK10/AN10,0)+IF(U10=1,AA10*AK10/AO10,0))*dt/60 -> 0.09017289 | AQ10: =E10+(AG10*SQRT(RTE)-AH10/SQRT(RTE))*dt/60/E_nom -> 0.62885117 | AR10: =IF(R10=1,1,0) -> 0
A11: 9 | B11: =A11/1440 -> 0.00625 | C11: 1.2588 | D11: =C11+P_aux -> 1.2738 | E11: =AQ10 -> 0.62885117 | F11: =AB10 -> 2.3 | G11: =IF(AND(S10=0,V10>=MinOff),V10,-1) -> -1 | H11: =IF(AND(T10=0,W10>=MinOff),W10,-1) -> -1 | I11: =IF(AND(U10=0,X10>=MinOff),X10,-1) -> 1007 | J11: =IF(AND(S10=1,V10>=MinRun),V10,-1) -> 1007 | K11: =IF(AND(T10=1,W10>=MinRun),W10,-1) -> 1007 | L11: =IF(AND(U10=1,X10>=MinRun),X10,-1) -> -1 | M11: =IF(MAX(G11:I11)<0,0,MATCH(MAX(G11:I11),G11:I11,0)) -> 3 | N11: =IF(MAX(J11:L11)<0,0,MATCH(MAX(J11:L11),J11:L11,0)) -> 1 | O11: =IF(N11=0,0,INDEX(CapVec,N11)) -> 1.2 | P11: =IF(OR(D11>F11+StartMargin,E11<SOC_startT),1,0) -> 0 | Q11: =IF(AND(E11>SOC_stopT,D11<=F11-O11+StopMargin),1,0) -> 0 | R11: =IF(AND(P11=1,M11>0),1,IF(AND(P11=0,Q11=1,N11>0),-1,0)) -> 0 | S11: =S10+IF(AND(R11=1,M11=1),1,0)-IF(AND(R11=-1,N11=1),1,0) -> 1 | T11: =T10+IF(AND(R11=1,M11=2),1,0)-IF(AND(R11=-1,N11=2),1,0) -> 1 | U11: =U10+IF(AND(R11=1,M11=3),1,0)-IF(AND(R11=-1,N11=3),1,0) -> 0 | V11: =IF(S11<>S10,0,V10+dt) -> 1008 | W11: =IF(T11<>T10,0,W10+dt) -> 1008 | X11: =IF(U11<>U10,0,X10+dt) -> 1008 | Y11: =S11*Cap_1*MIN(1,(V11+dt)/StartRamp) -> 1.2 | Z11: =T11*Cap_2*MIN(1,(W11+dt)/StartRamp) -> 1.1 | AA11: =U11*Cap_3*MIN(1,(X11+dt)/StartRamp) -> 0 | AB11: =SUM(Y11:AA11) -> 2.3 | AC11: =AB11-D11 -> 1.0262 | AD11: =MEDIAN(0,(TaperEnd-E11)/(TaperEnd-TaperStart),1) -> 1 | AE11: =MIN(P_pcs*AD11,MAX(0,SOC_max-E11)*E_nom*60/dt/SQRT(RTE)) -> 2.5 | AF11: =MIN(P_pcs,MAX(0,E11-SOC_min)*E_nom*60/dt*SQRT(RTE)) -> 2.5 | AG11: =IF(AC11>0,MIN(AC11,AE11),0) -> 1.0262 | AH11: =IF(AC11<0,MIN(-AC11,AF11),0) -> 0 | AI11: =IF(AC11>0,D11+AG11,AB11) -> 2.3 | AJ11: =MAX(0,D11-AI11-AH11) -> 0 | AK11: =IF(AB11>0,AI11/AB11,0) -> 1 | AL11: =IF(AB11=0,1,MIN(MATCH(MEDIAN(MinStable,AK11,1),FC_L,1),3)) -> 3 | AM11: =INDEX(FC_E1,$AL11)+(MEDIAN(MinStable,$AK11,1)-INDEX(FC_L,$AL11))*(INDEX(FC_E1,$AL11+1)-INDEX(FC_E1,$AL11))/(INDEX(FC_L,$AL11+1)-INDEX(FC_L,$AL11)) -> 0.428 | AN11: =INDEX(FC_E2,$AL11)+(MEDIAN(MinStable,$AK11,1)-INDEX(FC_L,$AL11))*(INDEX(FC_E2,$AL11+1)-INDEX(FC_E2,$AL11))/(INDEX(FC_L,$AL11+1)-INDEX(FC_L,$AL11)) -> 0.422 | AO11: =INDEX(FC_E3,$AL11)+(MEDIAN(MinStable,$AK11,1)-INDEX(FC_L,$AL11))*(INDEX(FC_E3,$AL11+1)-INDEX(FC_E3,$AL11))/(INDEX(FC_L,$AL11+1)-INDEX(FC_L,$AL11)) -> 0.415 | AP11: =(IF(S11=1,Y11*AK11/AM11,0)+IF(T11=1,Z11*AK11/AN11,0)+IF(U11=1,AA11*AK11/AO11,0))*dt/60 -> 0.09017289 | AQ11: =E11+(AG11*SQRT(RTE)-AH11/SQRT(RTE))*dt/60/E_nom -> 0.63176833 | AR11: =IF(R11=1,1,0) -> 0
A12: 10 | B12: =A12/1440 -> 0.0069444444 | C12: 1.1619 | D12: =C12+P_aux -> 1.1769 | E12: =AQ11 -> 0.63176833 | F12: =AB11 -> 2.3 | G12: =IF(AND(S11=0,V11>=MinOff),V11,-1) -> -1 | H12: =IF(AND(T11=0,W11>=MinOff),W11,-1) -> -1 | I12: =IF(AND(U11=0,X11>=MinOff),X11,-1) -> 1008 | J12: =IF(AND(S11=1,V11>=MinRun),V11,-1) -> 1008 | K12: =IF(AND(T11=1,W11>=MinRun),W11,-1) -> 1008 | L12: =IF(AND(U11=1,X11>=MinRun),X11,-1) -> -1 | M12: =IF(MAX(G12:I12)<0,0,MATCH(MAX(G12:I12),G12:I12,0)) -> 3 | N12: =IF(MAX(J12:L12)<0,0,MATCH(MAX(J12:L12),J12:L12,0)) -> 1 | O12: =IF(N12=0,0,INDEX(CapVec,N12)) -> 1.2 | P12: =IF(OR(D12>F12+StartMargin,E12<SOC_startT),1,0) -> 0 | Q12: =IF(AND(E12>SOC_stopT,D12<=F12-O12+StopMargin),1,0) -> 0 | R12: =IF(AND(P12=1,M12>0),1,IF(AND(P12=0,Q12=1,N12>0),-1,0)) -> 0 | S12: =S11+IF(AND(R12=1,M12=1),1,0)-IF(AND(R12=-1,N12=1),1,0) -> 1 | T12: =T11+IF(AND(R12=1,M12=2),1,0)-IF(AND(R12=-1,N12=2),1,0) -> 1 | U12: =U11+IF(AND(R12=1,M12=3),1,0)-IF(AND(R12=-1,N12=3),1,0) -> 0 | V12: =IF(S12<>S11,0,V11+dt) -> 1009 | W12: =IF(T12<>T11,0,W11+dt) -> 1009 | X12: =IF(U12<>U11,0,X11+dt) -> 1009 | Y12: =S12*Cap_1*MIN(1,(V12+dt)/StartRamp) -> 1.2 | Z12: =T12*Cap_2*MIN(1,(W12+dt)/StartRamp) -> 1.1 | AA12: =U12*Cap_3*MIN(1,(X12+dt)/StartRamp) -> 0 | AB12: =SUM(Y12:AA12) -> 2.3 | AC12: =AB12-D12 -> 1.1231 | AD12: =MEDIAN(0,(TaperEnd-E12)/(TaperEnd-TaperStart),1) -> 1 | AE12: =MIN(P_pcs*AD12,MAX(0,SOC_max-E12)*E_nom*60/dt/SQRT(RTE)) -> 2.5 | AF12: =MIN(P_pcs,MAX(0,E12-SOC_min)*E_nom*60/dt*SQRT(RTE)) -> 2.5 | AG12: =IF(AC12>0,MIN(AC12,AE12),0) -> 1.1231 | AH12: =IF(AC12<0,MIN(-AC12,AF12),0) -> 0 | AI12: =IF(AC12>0,D12+AG12,AB12) -> 2.3 | AJ12: =MAX(0,D12-AI12-AH12) -> 0 | AK12: =IF(AB12>0,AI12/AB12,0) -> 1 | AL12: =IF(AB12=0,1,MIN(MATCH(MEDIAN(MinStable,AK12,1),FC_L,1),3)) -> 3 | AM12: =INDEX(FC_E1,$AL12)+(MEDIAN(MinStable,$AK12,1)-INDEX(FC_L,$AL12))*(INDEX(FC_E1,$AL12+1)-INDEX(FC_E1,$AL12))/(INDEX(FC_L,$AL12+1)-INDEX(FC_L,$AL12)) -> 0.428 | AN12: =INDEX(FC_E2,$AL12)+(MEDIAN(MinStable,$AK12,1)-INDEX(FC_L,$AL12))*(INDEX(FC_E2,$AL12+1)-INDEX(FC_E2,$AL12))/(INDEX(FC_L,$AL12+1)-INDEX(FC_L,$AL12)) -> 0.422 | AO12: =INDEX(FC_E3,$AL12)+(MEDIAN(MinStable,$AK12,1)-INDEX(FC_L,$AL12))*(INDEX(FC_E3,$AL12+1)-INDEX(FC_E3,$AL12))/(INDEX(FC_L,$AL12+1)-INDEX(FC_L,$AL12)) -> 0.415 | AP12: =(IF(S12=1,Y12*AK12/AM12,0)+IF(T12=1,Z12*AK12/AN12,0)+IF(U12=1,AA12*AK12/AO12,0))*dt/60 -> 0.09017289 | AQ12: =E12+(AG12*SQRT(RTE)-AH12/SQRT(RTE))*dt/60/E_nom -> 0.63496094 | AR12: =IF(R12=1,1,0) -> 0
A13: 11 | B13: =A13/1440 -> 0.0076388889 | C13: 1.097 | D13: =C13+P_aux -> 1.112 | E13: =AQ12 -> 0.63496094 | F13: =AB12 -> 2.3 | G13: =IF(AND(S12=0,V12>=MinOff),V12,-1) -> -1 | H13: =IF(AND(T12=0,W12>=MinOff),W12,-1) -> -1 | I13: =IF(AND(U12=0,X12>=MinOff),X12,-1) -> 1009 | J13: =IF(AND(S12=1,V12>=MinRun),V12,-1) -> 1009 | K13: =IF(AND(T12=1,W12>=MinRun),W12,-1) -> 1009 | L13: =IF(AND(U12=1,X12>=MinRun),X12,-1) -> -1 | M13: =IF(MAX(G13:I13)<0,0,MATCH(MAX(G13:I13),G13:I13,0)) -> 3 | N13: =IF(MAX(J13:L13)<0,0,MATCH(MAX(J13:L13),J13:L13,0)) -> 1 | O13: =IF(N13=0,0,INDEX(CapVec,N13)) -> 1.2 | P13: =IF(OR(D13>F13+StartMargin,E13<SOC_startT),1,0) -> 0 | Q13: =IF(AND(E13>SOC_stopT,D13<=F13-O13+StopMargin),1,0) -> 0 | R13: =IF(AND(P13=1,M13>0),1,IF(AND(P13=0,Q13=1,N13>0),-1,0)) -> 0 | S13: =S12+IF(AND(R13=1,M13=1),1,0)-IF(AND(R13=-1,N13=1),1,0) -> 1 | T13: =T12+IF(AND(R13=1,M13=2),1,0)-IF(AND(R13=-1,N13=2),1,0) -> 1 | U13: =U12+IF(AND(R13=1,M13=3),1,0)-IF(AND(R13=-1,N13=3),1,0) -> 0 | V13: =IF(S13<>S12,0,V12+dt) -> 1010 | W13: =IF(T13<>T12,0,W12+dt) -> 1010 | X13: =IF(U13<>U12,0,X12+dt) -> 1010 | Y13: =S13*Cap_1*MIN(1,(V13+dt)/StartRamp) -> 1.2 | Z13: =T13*Cap_2*MIN(1,(W13+dt)/StartRamp) -> 1.1 | AA13: =U13*Cap_3*MIN(1,(X13+dt)/StartRamp) -> 0 | AB13: =SUM(Y13:AA13) -> 2.3 | AC13: =AB13-D13 -> 1.188 | AD13: =MEDIAN(0,(TaperEnd-E13)/(TaperEnd-TaperStart),1) -> 1 | AE13: =MIN(P_pcs*AD13,MAX(0,SOC_max-E13)*E_nom*60/dt/SQRT(RTE)) -> 2.5 | AF13: =MIN(P_pcs,MAX(0,E13-SOC_min)*E_nom*60/dt*SQRT(RTE)) -> 2.5 | AG13: =IF(AC13>0,MIN(AC13,AE13),0) -> 1.188 | AH13: =IF(AC13<0,MIN(-AC13,AF13),0) -> 0 | AI13: =IF(AC13>0,D13+AG13,AB13) -> 2.3 | AJ13: =MAX(0,D13-AI13-AH13) -> 0 | AK13: =IF(AB13>0,AI13/AB13,0) -> 1 | AL13: =IF(AB13=0,1,MIN(MATCH(MEDIAN(MinStable,AK13,1),FC_L,1),3)) -> 3 | AM13: =INDEX(FC_E1,$AL13)+(MEDIAN(MinStable,$AK13,1)-INDEX(FC_L,$AL13))*(INDEX(FC_E1,$AL13+1)-INDEX(FC_E1,$AL13))/(INDEX(FC_L,$AL13+1)-INDEX(FC_L,$AL13)) -> 0.428 | AN13: =INDEX(FC_E2,$AL13)+(MEDIAN(MinStable,$AK13,1)-INDEX(FC_L,$AL13))*(INDEX(FC_E2,$AL13+1)-INDEX(FC_E2,$AL13))/(INDEX(FC_L,$AL13+1)-INDEX(FC_L,$AL13)) -> 0.422 | AO13: =INDEX(FC_E3,$AL13)+(MEDIAN(MinStable,$AK13,1)-INDEX(FC_L,$AL13))*(INDEX(FC_E3,$AL13+1)-INDEX(FC_E3,$AL13))/(INDEX(FC_L,$AL13+1)-INDEX(FC_L,$AL13)) -> 0.415 | AP13: =(IF(S13=1,Y13*AK13/AM13,0)+IF(T13=1,Z13*AK13/AN13,0)+IF(U13=1,AA13*AK13/AO13,0))*dt/60 -> 0.09017289 | AQ13: =E13+(AG13*SQRT(RTE)-AH13/SQRT(RTE))*dt/60/E_nom -> 0.63833804 | AR13: =IF(R13=1,1,0) -> 0
A14: 12 | B14: =A14/1440 -> 0.0083333333 | C14: 1.287 | D14: =C14+P_aux -> 1.302 | E14: =AQ13 -> 0.63833804 | F14: =AB13 -> 2.3 | G14: =IF(AND(S13=0,V13>=MinOff),V13,-1) -> -1 | H14: =IF(AND(T13=0,W13>=MinOff),W13,-1) -> -1 | I14: =IF(AND(U13=0,X13>=MinOff),X13,-1) -> 1010 | J14: =IF(AND(S13=1,V13>=MinRun),V13,-1) -> 1010 | K14: =IF(AND(T13=1,W13>=MinRun),W13,-1) -> 1010 | L14: =IF(AND(U13=1,X13>=MinRun),X13,-1) -> -1 | M14: =IF(MAX(G14:I14)<0,0,MATCH(MAX(G14:I14),G14:I14,0)) -> 3 | N14: =IF(MAX(J14:L14)<0,0,MATCH(MAX(J14:L14),J14:L14,0)) -> 1 | O14: =IF(N14=0,0,INDEX(CapVec,N14)) -> 1.2 | P14: =IF(OR(D14>F14+StartMargin,E14<SOC_startT),1,0) -> 0 | Q14: =IF(AND(E14>SOC_stopT,D14<=F14-O14+StopMargin),1,0) -> 0 | R14: =IF(AND(P14=1,M14>0),1,IF(AND(P14=0,Q14=1,N14>0),-1,0)) -> 0 | S14: =S13+IF(AND(R14=1,M14=1),1,0)-IF(AND(R14=-1,N14=1),1,0) -> 1 | T14: =T13+IF(AND(R14=1,M14=2),1,0)-IF(AND(R14=-1,N14=2),1,0) -> 1 | U14: =U13+IF(AND(R14=1,M14=3),1,0)-IF(AND(R14=-1,N14=3),1,0) -> 0 | V14: =IF(S14<>S13,0,V13+dt) -> 1011 | W14: =IF(T14<>T13,0,W13+dt) -> 1011 | X14: =IF(U14<>U13,0,X13+dt) -> 1011 | Y14: =S14*Cap_1*MIN(1,(V14+dt)/StartRamp) -> 1.2 | Z14: =T14*Cap_2*MIN(1,(W14+dt)/StartRamp) -> 1.1 | AA14: =U14*Cap_3*MIN(1,(X14+dt)/StartRamp) -> 0 | AB14: =SUM(Y14:AA14) -> 2.3 | AC14: =AB14-D14 -> 0.998 | AD14: =MEDIAN(0,(TaperEnd-E14)/(TaperEnd-TaperStart),1) -> 1 | AE14: =MIN(P_pcs*AD14,MAX(0,SOC_max-E14)*E_nom*60/dt/SQRT(RTE)) -> 2.5 | AF14: =MIN(P_pcs,MAX(0,E14-SOC_min)*E_nom*60/dt*SQRT(RTE)) -> 2.5 | AG14: =IF(AC14>0,MIN(AC14,AE14),0) -> 0.998 | AH14: =IF(AC14<0,MIN(-AC14,AF14),0) -> 0 | AI14: =IF(AC14>0,D14+AG14,AB14) -> 2.3 | AJ14: =MAX(0,D14-AI14-AH14) -> 0 | AK14: =IF(AB14>0,AI14/AB14,0) -> 1 | AL14: =IF(AB14=0,1,MIN(MATCH(MEDIAN(MinStable,AK14,1),FC_L,1),3)) -> 3 | AM14: =INDEX(FC_E1,$AL14)+(MEDIAN(MinStable,$AK14,1)-INDEX(FC_L,$AL14))*(INDEX(FC_E1,$AL14+1)-INDEX(FC_E1,$AL14))/(INDEX(FC_L,$AL14+1)-INDEX(FC_L,$AL14)) -> 0.428 | AN14: =INDEX(FC_E2,$AL14)+(MEDIAN(MinStable,$AK14,1)-INDEX(FC_L,$AL14))*(INDEX(FC_E2,$AL14+1)-INDEX(FC_E2,$AL14))/(INDEX(FC_L,$AL14+1)-INDEX(FC_L,$AL14)) -> 0.422 | AO14: =INDEX(FC_E3,$AL14)+(MEDIAN(MinStable,$AK14,1)-INDEX(FC_L,$AL14))*(INDEX(FC_E3,$AL14+1)-INDEX(FC_E3,$AL14))/(INDEX(FC_L,$AL14+1)-INDEX(FC_L,$AL14)) -> 0.415 | AP14: =(IF(S14=1,Y14*AK14/AM14,0)+IF(T14=1,Z14*AK14/AN14,0)+IF(U14=1,AA14*AK14/AO14,0))*dt/60 -> 0.09017289 | AQ14: =E14+(AG14*SQRT(RTE)-AH14/SQRT(RTE))*dt/60/E_nom -> 0.64117503 | AR14: =IF(R14=1,1,0) -> 0
... A1441: 1439 | B1441: =A1441/1440 -> 0.99930556 | C1441: 1.2226 | D1441: =C1441+P_aux -> 1.2376 | E1441: =AQ1440 -> 0.49880761 | F1441: =AB1440 -> 1.1 | G1441: =IF(AND(S1440=0,V1440>=MinOff),V1440,-1) -> 133 | H1441: =IF(AND(T1440=0,W1440>=MinOff),W1440,-1) -> 132 | I1441: =IF(AND(U1440=0,X1440>=MinOff),X1440,-1) -> -1 | J1441: =IF(AND(S1440=1,V1440>=MinRun),V1440,-1) -> -1 | K1441: =IF(AND(T1440=1,W1440>=MinRun),W1440,-1) -> -1 | L1441: =IF(AND(U1440=1,X1440>=MinRun),X1440,-1) -> 874 | M1441: =IF(MAX(G1441:I1441)<0,0,MATCH(MAX(G1441:I1441),G1441:I1441,0)) -> 1 | N1441: =IF(MAX(J1441:L1441)<0,0,MATCH(MAX(J1441:L1441),J1441:L1441,0)) -> 3 | O1441: =IF(N1441=0,0,INDEX(CapVec,N1441)) -> 1.1 | P1441: =IF(OR(D1441>F1441+StartMargin,E1441<SOC_startT),1,0) -> 0 | Q1441: =IF(AND(E1441>SOC_stopT,D1441<=F1441-O1441+StopMargin),1,0) -> 0 | R1441: =IF(AND(P1441=1,M1441>0),1,IF(AND(P1441=0,Q1441=1,N1441>0),-1,0)) -> 0 | S1441: =S1440+IF(AND(R1441=1,M1441=1),1,0)-IF(AND(R1441=-1,N1441=1),1,0) -> 0 | T1441: =T1440+IF(AND(R1441=1,M1441=2),1,0)-IF(AND(R1441=-1,N1441=2),1,0) -> 0 | U1441: =U1440+IF(AND(R1441=1,M1441=3),1,0)-IF(AND(R1441=-1,N1441=3),1,0) -> 1 | V1441: =IF(S1441<>S1440,0,V1440+dt) -> 134 | W1441: =IF(T1441<>T1440,0,W1440+dt) -> 133 | X1441: =IF(U1441<>U1440,0,X1440+dt) -> 875 | Y1441: =S1441*Cap_1*MIN(1,(V1441+dt)/StartRamp) -> 0 | Z1441: =T1441*Cap_2*MIN(1,(W1441+dt)/StartRamp) -> 0 | AA1441: =U1441*Cap_3*MIN(1,(X1441+dt)/StartRamp) -> 1.1 | AB1441: =SUM(Y1441:AA1441) -> 1.1 | AC1441: =AB1441-D1441 -> -0.1376 | AD1441: =MEDIAN(0,(TaperEnd-E1441)/(TaperEnd-TaperStart),1) -> 1 | AE1441: =MIN(P_pcs*AD1441,MAX(0,SOC_max-E1441)*E_nom*60/dt/SQRT(RTE)) -> 2.5 | AF1441: =MIN(P_pcs,MAX(0,E1441-SOC_min)*E_nom*60/dt*SQRT(RTE)) -> 2.5 | AG1441: =IF(AC1441>0,MIN(AC1441,AE1441),0) -> 0 | AH1441: =IF(AC1441<0,MIN(-AC1441,AF1441),0) -> 0.1376 | AI1441: =IF(AC1441>0,D1441+AG1441,AB1441) -> 1.1 | AJ1441: =MAX(0,D1441-AI1441-AH1441) -> 0 | AK1441: =IF(AB1441>0,AI1441/AB1441,0) -> 1 | AL1441: =IF(AB1441=0,1,MIN(MATCH(MEDIAN(MinStable,AK1441,1),FC_L,1),3)) -> 3 | AM1441: =INDEX(FC_E1,$AL1441)+(MEDIAN(MinStable,$AK1441,1)-INDEX(FC_L,$AL1441))*(INDEX(FC_E1,$AL1441+1)-INDEX(FC_E1,$AL1441))/(INDEX(FC_L,$AL1441+1)-INDEX(FC_L,$AL1441)) -> 0.428 | AN1441: =INDEX(FC_E2,$AL1441)+(MEDIAN(MinStable,$AK1441,1)-INDEX(FC_L,$AL1441))*(INDEX(FC_E2,$AL1441+1)-INDEX(FC_E2,$AL1441))/(INDEX(FC_L,$AL1441+1)-INDEX(FC_L,$AL1441)) -> 0.422 | AO1441: =INDEX(FC_E3,$AL1441)+(MEDIAN(MinStable,$AK1441,1)-INDEX(FC_L,$AL1441))*(INDEX(FC_E3,$AL1441+1)-INDEX(FC_E3,$AL1441))/(INDEX(FC_L,$AL1441+1)-INDEX(FC_L,$AL1441)) -> 0.415 | AP1441: =(IF(S1441=1,Y1441*AK1441/AM1441,0)+IF(T1441=1,Z1441*AK1441/AN1441,0)+IF(U1441=1,AA1441*AK1441/AO1441,0))*dt/60 -> 0.044176707 | AQ1441: =E1441+(AG1441*SQRT(RTE)-AH1441/SQRT(RTE))*dt/60/E_nom -> 0.49836312 | AR1441: =IF(R1441=1,1,0) -> 0

Sheet Baseline
A1: t (min) | B1: Time | C1: Process load (MW) | D1: Capacity (MW) | E1: CHP output (MW) | F1: Loading (frac) | G1: Grid import (MW) | H1: Curtailed (MW) | I1: Curve idx | J1: Eff U1 | K1: Eff U2 | L1: Eff U3 | M1: Gas (MWh)
A2: 0 | B2: =A2/1440 -> 0 | C2: =Sim!C2 -> 1.172 | D2: =Cap_base -> 3.4 | E2: =MEDIAN(MinStable*D2,C2,D2) -> 1.7 | F2: =E2/D2 -> 0.5 | G2: =MAX(0,C2-E2) -> 0 | H2: =MAX(0,E2-C2) -> 0.528 | I2: =MIN(MATCH(MEDIAN(MinStable,F2,1),FC_L,1),3) -> 2 | J2: =INDEX(FC_E1,$I2)+(MEDIAN(MinStable,$F2,1)-INDEX(FC_L,$I2))*(INDEX(FC_E1,$I2+1)-INDEX(FC_E1,$I2))/(INDEX(FC_L,$I2+1)-INDEX(FC_L,$I2)) -> 0.365 | K2: =INDEX(FC_E2,$I2)+(MEDIAN(MinStable,$F2,1)-INDEX(FC_L,$I2))*(INDEX(FC_E2,$I2+1)-INDEX(FC_E2,$I2))/(INDEX(FC_L,$I2+1)-INDEX(FC_L,$I2)) -> 0.36 | L2: =INDEX(FC_E3,$I2)+(MEDIAN(MinStable,$F2,1)-INDEX(FC_L,$I2))*(INDEX(FC_E3,$I2+1)-INDEX(FC_E3,$I2))/(INDEX(FC_L,$I2+1)-INDEX(FC_L,$I2)) -> 0.354 | M2: =(Cap_1*F2/J2+IF(N_base>=2,Cap_2*F2/K2,0)+IF(N_base>=3,Cap_3*F2/L2,0))*dt/60 -> 0.078754762
A3: 1 | B3: =A3/1440 -> 0.00069444444 | C3: =Sim!C3 -> 1.1482 | D3: =Cap_base -> 3.4 | E3: =MEDIAN(MinStable*D3,C3,D3) -> 1.7 | F3: =E3/D3 -> 0.5 | G3: =MAX(0,C3-E3) -> 0 | H3: =MAX(0,E3-C3) -> 0.5518 | I3: =MIN(MATCH(MEDIAN(MinStable,F3,1),FC_L,1),3) -> 2 | J3: =INDEX(FC_E1,$I3)+(MEDIAN(MinStable,$F3,1)-INDEX(FC_L,$I3))*(INDEX(FC_E1,$I3+1)-INDEX(FC_E1,$I3))/(INDEX(FC_L,$I3+1)-INDEX(FC_L,$I3)) -> 0.365 | K3: =INDEX(FC_E2,$I3)+(MEDIAN(MinStable,$F3,1)-INDEX(FC_L,$I3))*(INDEX(FC_E2,$I3+1)-INDEX(FC_E2,$I3))/(INDEX(FC_L,$I3+1)-INDEX(FC_L,$I3)) -> 0.36 | L3: =INDEX(FC_E3,$I3)+(MEDIAN(MinStable,$F3,1)-INDEX(FC_L,$I3))*(INDEX(FC_E3,$I3+1)-INDEX(FC_E3,$I3))/(INDEX(FC_L,$I3+1)-INDEX(FC_L,$I3)) -> 0.354 | M3: =(Cap_1*F3/J3+IF(N_base>=2,Cap_2*F3/K3,0)+IF(N_base>=3,Cap_3*F3/L3,0))*dt/60 -> 0.078754762
A4: 2 | B4: =A4/1440 -> 0.0013888889 | C4: =Sim!C4 -> 1.1061 | D4: =Cap_base -> 3.4 | E4: =MEDIAN(MinStable*D4,C4,D4) -> 1.7 | F4: =E4/D4 -> 0.5 | G4: =MAX(0,C4-E4) -> 0 | H4: =MAX(0,E4-C4) -> 0.5939 | I4: =MIN(MATCH(MEDIAN(MinStable,F4,1),FC_L,1),3) -> 2 | J4: =INDEX(FC_E1,$I4)+(MEDIAN(MinStable,$F4,1)-INDEX(FC_L,$I4))*(INDEX(FC_E1,$I4+1)-INDEX(FC_E1,$I4))/(INDEX(FC_L,$I4+1)-INDEX(FC_L,$I4)) -> 0.365 | K4: =INDEX(FC_E2,$I4)+(MEDIAN(MinStable,$F4,1)-INDEX(FC_L,$I4))*(INDEX(FC_E2,$I4+1)-INDEX(FC_E2,$I4))/(INDEX(FC_L,$I4+1)-INDEX(FC_L,$I4)) -> 0.36 | L4: =INDEX(FC_E3,$I4)+(MEDIAN(MinStable,$F4,1)-INDEX(FC_L,$I4))*(INDEX(FC_E3,$I4+1)-INDEX(FC_E3,$I4))/(INDEX(FC_L,$I4+1)-INDEX(FC_L,$I4)) -> 0.354 | M4: =(Cap_1*F4/J4+IF(N_base>=2,Cap_2*F4/K4,0)+IF(N_base>=3,Cap_3*F4/L4,0))*dt/60 -> 0.078754762
A5: 3 | B5: =A5/1440 -> 0.0020833333 | C5: =Sim!C5 -> 1.1643 | D5: =Cap_base -> 3.4 | E5: =MEDIAN(MinStable*D5,C5,D5) -> 1.7 | F5: =E5/D5 -> 0.5 | G5: =MAX(0,C5-E5) -> 0 | H5: =MAX(0,E5-C5) -> 0.5357 | I5: =MIN(MATCH(MEDIAN(MinStable,F5,1),FC_L,1),3) -> 2 | J5: =INDEX(FC_E1,$I5)+(MEDIAN(MinStable,$F5,1)-INDEX(FC_L,$I5))*(INDEX(FC_E1,$I5+1)-INDEX(FC_E1,$I5))/(INDEX(FC_L,$I5+1)-INDEX(FC_L,$I5)) -> 0.365 | K5: =INDEX(FC_E2,$I5)+(MEDIAN(MinStable,$F5,1)-INDEX(FC_L,$I5))*(INDEX(FC_E2,$I5+1)-INDEX(FC_E2,$I5))/(INDEX(FC_L,$I5+1)-INDEX(FC_L,$I5)) -> 0.36 | L5: =INDEX(FC_E3,$I5)+(MEDIAN(MinStable,$F5,1)-INDEX(FC_L,$I5))*(INDEX(FC_E3,$I5+1)-INDEX(FC_E3,$I5))/(INDEX(FC_L,$I5+1)-INDEX(FC_L,$I5)) -> 0.354 | M5: =(Cap_1*F5/J5+IF(N_base>=2,Cap_2*F5/K5,0)+IF(N_base>=3,Cap_3*F5/L5,0))*dt/60 -> 0.078754762
A6: 4 | B6: =A6/1440 -> 0.0027777778 | C6: =Sim!C6 -> 1.1384 | D6: =Cap_base -> 3.4 | E6: =MEDIAN(MinStable*D6,C6,D6) -> 1.7 | F6: =E6/D6 -> 0.5 | G6: =MAX(0,C6-E6) -> 0 | H6: =MAX(0,E6-C6) -> 0.5616 | I6: =MIN(MATCH(MEDIAN(MinStable,F6,1),FC_L,1),3) -> 2 | J6: =INDEX(FC_E1,$I6)+(MEDIAN(MinStable,$F6,1)-INDEX(FC_L,$I6))*(INDEX(FC_E1,$I6+1)-INDEX(FC_E1,$I6))/(INDEX(FC_L,$I6+1)-INDEX(FC_L,$I6)) -> 0.365 | K6: =INDEX(FC_E2,$I6)+(MEDIAN(MinStable,$F6,1)-INDEX(FC_L,$I6))*(INDEX(FC_E2,$I6+1)-INDEX(FC_E2,$I6))/(INDEX(FC_L,$I6+1)-INDEX(FC_L,$I6)) -> 0.36 | L6: =INDEX(FC_E3,$I6)+(MEDIAN(MinStable,$F6,1)-INDEX(FC_L,$I6))*(INDEX(FC_E3,$I6+1)-INDEX(FC_E3,$I6))/(INDEX(FC_L,$I6+1)-INDEX(FC_L,$I6)) -> 0.354 | M6: =(Cap_1*F6/J6+IF(N_base>=2,Cap_2*F6/K6,0)+IF(N_base>=3,Cap_3*F6/L6,0))*dt/60 -> 0.078754762
A7: 5 | B7: =A7/1440 -> 0.0034722222 | C7: =Sim!C7 -> 1.2374 | D7: =Cap_base -> 3.4 | E7: =MEDIAN(MinStable*D7,C7,D7) -> 1.7 | F7: =E7/D7 -> 0.5 | G7: =MAX(0,C7-E7) -> 0 | H7: =MAX(0,E7-C7) -> 0.4626 | I7: =MIN(MATCH(MEDIAN(MinStable,F7,1),FC_L,1),3) -> 2 | J7: =INDEX(FC_E1,$I7)+(MEDIAN(MinStable,$F7,1)-INDEX(FC_L,$I7))*(INDEX(FC_E1,$I7+1)-INDEX(FC_E1,$I7))/(INDEX(FC_L,$I7+1)-INDEX(FC_L,$I7)) -> 0.365 | K7: =INDEX(FC_E2,$I7)+(MEDIAN(MinStable,$F7,1)-INDEX(FC_L,$I7))*(INDEX(FC_E2,$I7+1)-INDEX(FC_E2,$I7))/(INDEX(FC_L,$I7+1)-INDEX(FC_L,$I7)) -> 0.36 | L7: =INDEX(FC_E3,$I7)+(MEDIAN(MinStable,$F7,1)-INDEX(FC_L,$I7))*(INDEX(FC_E3,$I7+1)-INDEX(FC_E3,$I7))/(INDEX(FC_L,$I7+1)-INDEX(FC_L,$I7)) -> 0.354 | M7: =(Cap_1*F7/J7+IF(N_base>=2,Cap_2*F7/K7,0)+IF(N_base>=3,Cap_3*F7/L7,0))*dt/60 -> 0.078754762
A8: 6 | B8: =A8/1440 -> 0.0041666667 | C8: =Sim!C8 -> 1.2077 | D8: =Cap_base -> 3.4 | E8: =MEDIAN(MinStable*D8,C8,D8) -> 1.7 | F8: =E8/D8 -> 0.5 | G8: =MAX(0,C8-E8) -> 0 | H8: =MAX(0,E8-C8) -> 0.4923 | I8: =MIN(MATCH(MEDIAN(MinStable,F8,1),FC_L,1),3) -> 2 | J8: =INDEX(FC_E1,$I8)+(MEDIAN(MinStable,$F8,1)-INDEX(FC_L,$I8))*(INDEX(FC_E1,$I8+1)-INDEX(FC_E1,$I8))/(INDEX(FC_L,$I8+1)-INDEX(FC_L,$I8)) -> 0.365 | K8: =INDEX(FC_E2,$I8)+(MEDIAN(MinStable,$F8,1)-INDEX(FC_L,$I8))*(INDEX(FC_E2,$I8+1)-INDEX(FC_E2,$I8))/(INDEX(FC_L,$I8+1)-INDEX(FC_L,$I8)) -> 0.36 | L8: =INDEX(FC_E3,$I8)+(MEDIAN(MinStable,$F8,1)-INDEX(FC_L,$I8))*(INDEX(FC_E3,$I8+1)-INDEX(FC_E3,$I8))/(INDEX(FC_L,$I8+1)-INDEX(FC_L,$I8)) -> 0.354 | M8: =(Cap_1*F8/J8+IF(N_base>=2,Cap_2*F8/K8,0)+IF(N_base>=3,Cap_3*F8/L8,0))*dt/60 -> 0.078754762
A9: 7 | B9: =A9/1440 -> 0.0048611111 | C9: =Sim!C9 -> 1.1476 | D9: =Cap_base -> 3.4 | E9: =MEDIAN(MinStable*D9,C9,D9) -> 1.7 | F9: =E9/D9 -> 0.5 | G9: =MAX(0,C9-E9) -> 0 | H9: =MAX(0,E9-C9) -> 0.5524 | I9: =MIN(MATCH(MEDIAN(MinStable,F9,1),FC_L,1),3) -> 2 | J9: =INDEX(FC_E1,$I9)+(MEDIAN(MinStable,$F9,1)-INDEX(FC_L,$I9))*(INDEX(FC_E1,$I9+1)-INDEX(FC_E1,$I9))/(INDEX(FC_L,$I9+1)-INDEX(FC_L,$I9)) -> 0.365 | K9: =INDEX(FC_E2,$I9)+(MEDIAN(MinStable,$F9,1)-INDEX(FC_L,$I9))*(INDEX(FC_E2,$I9+1)-INDEX(FC_E2,$I9))/(INDEX(FC_L,$I9+1)-INDEX(FC_L,$I9)) -> 0.36 | L9: =INDEX(FC_E3,$I9)+(MEDIAN(MinStable,$F9,1)-INDEX(FC_L,$I9))*(INDEX(FC_E3,$I9+1)-INDEX(FC_E3,$I9))/(INDEX(FC_L,$I9+1)-INDEX(FC_L,$I9)) -> 0.354 | M9: =(Cap_1*F9/J9+IF(N_base>=2,Cap_2*F9/K9,0)+IF(N_base>=3,Cap_3*F9/L9,0))*dt/60 -> 0.078754762
A10: 8 | B10: =A10/1440 -> 0.0055555556 | C10: =Sim!C10 -> 1.094 | D10: =Cap_base -> 3.4 | E10: =MEDIAN(MinStable*D10,C10,D10) -> 1.7 | F10: =E10/D10 -> 0.5 | G10: =MAX(0,C10-E10) -> 0 | H10: =MAX(0,E10-C10) -> 0.606 | I10: =MIN(MATCH(MEDIAN(MinStable,F10,1),FC_L,1),3) -> 2 | J10: =INDEX(FC_E1,$I10)+(MEDIAN(MinStable,$F10,1)-INDEX(FC_L,$I10))*(INDEX(FC_E1,$I10+1)-INDEX(FC_E1,$I10))/(INDEX(FC_L,$I10+1)-INDEX(FC_L,$I10)) -> 0.365 | K10: =INDEX(FC_E2,$I10)+(MEDIAN(MinStable,$F10,1)-INDEX(FC_L,$I10))*(INDEX(FC_E2,$I10+1)-INDEX(FC_E2,$I10))/(INDEX(FC_L,$I10+1)-INDEX(FC_L,$I10)) -> 0.36 | L10: =INDEX(FC_E3,$I10)+(MEDIAN(MinStable,$F10,1)-INDEX(FC_L,$I10))*(INDEX(FC_E3,$I10+1)-INDEX(FC_E3,$I10))/(INDEX(FC_L,$I10+1)-INDEX(FC_L,$I10)) -> 0.354 | M10: =(Cap_1*F10/J10+IF(N_base>=2,Cap_2*F10/K10,0)+IF(N_base>=3,Cap_3*F10/L10,0))*dt/60 -> 0.078754762
A11: 9 | B11: =A11/1440 -> 0.00625 | C11: =Sim!C11 -> 1.2588 | D11: =Cap_base -> 3.4 | E11: =MEDIAN(MinStable*D11,C11,D11) -> 1.7 | F11: =E11/D11 -> 0.5 | G11: =MAX(0,C11-E11) -> 0 | H11: =MAX(0,E11-C11) -> 0.4412 | I11: =MIN(MATCH(MEDIAN(MinStable,F11,1),FC_L,1),3) -> 2 | J11: =INDEX(FC_E1,$I11)+(MEDIAN(MinStable,$F11,1)-INDEX(FC_L,$I11))*(INDEX(FC_E1,$I11+1)-INDEX(FC_E1,$I11))/(INDEX(FC_L,$I11+1)-INDEX(FC_L,$I11)) -> 0.365 | K11: =INDEX(FC_E2,$I11)+(MEDIAN(MinStable,$F11,1)-INDEX(FC_L,$I11))*(INDEX(FC_E2,$I11+1)-INDEX(FC_E2,$I11))/(INDEX(FC_L,$I11+1)-INDEX(FC_L,$I11)) -> 0.36 | L11: =INDEX(FC_E3,$I11)+(MEDIAN(MinStable,$F11,1)-INDEX(FC_L,$I11))*(INDEX(FC_E3,$I11+1)-INDEX(FC_E3,$I11))/(INDEX(FC_L,$I11+1)-INDEX(FC_L,$I11)) -> 0.354 | M11: =(Cap_1*F11/J11+IF(N_base>=2,Cap_2*F11/K11,0)+IF(N_base>=3,Cap_3*F11/L11,0))*dt/60 -> 0.078754762
A12: 10 | B12: =A12/1440 -> 0.0069444444 | C12: =Sim!C12 -> 1.1619 | D12: =Cap_base -> 3.4 | E12: =MEDIAN(MinStable*D12,C12,D12) -> 1.7 | F12: =E12/D12 -> 0.5 | G12: =MAX(0,C12-E12) -> 0 | H12: =MAX(0,E12-C12) -> 0.5381 | I12: =MIN(MATCH(MEDIAN(MinStable,F12,1),FC_L,1),3) -> 2 | J12: =INDEX(FC_E1,$I12)+(MEDIAN(MinStable,$F12,1)-INDEX(FC_L,$I12))*(INDEX(FC_E1,$I12+1)-INDEX(FC_E1,$I12))/(INDEX(FC_L,$I12+1)-INDEX(FC_L,$I12)) -> 0.365 | K12: =INDEX(FC_E2,$I12)+(MEDIAN(MinStable,$F12,1)-INDEX(FC_L,$I12))*(INDEX(FC_E2,$I12+1)-INDEX(FC_E2,$I12))/(INDEX(FC_L,$I12+1)-INDEX(FC_L,$I12)) -> 0.36 | L12: =INDEX(FC_E3,$I12)+(MEDIAN(MinStable,$F12,1)-INDEX(FC_L,$I12))*(INDEX(FC_E3,$I12+1)-INDEX(FC_E3,$I12))/(INDEX(FC_L,$I12+1)-INDEX(FC_L,$I12)) -> 0.354 | M12: =(Cap_1*F12/J12+IF(N_base>=2,Cap_2*F12/K12,0)+IF(N_base>=3,Cap_3*F12/L12,0))*dt/60 -> 0.078754762
A13: 11 | B13: =A13/1440 -> 0.0076388889 | C13: =Sim!C13 -> 1.097 | D13: =Cap_base -> 3.4 | E13: =MEDIAN(MinStable*D13,C13,D13) -> 1.7 | F13: =E13/D13 -> 0.5 | G13: =MAX(0,C13-E13) -> 0 | H13: =MAX(0,E13-C13) -> 0.603 | I13: =MIN(MATCH(MEDIAN(MinStable,F13,1),FC_L,1),3) -> 2 | J13: =INDEX(FC_E1,$I13)+(MEDIAN(MinStable,$F13,1)-INDEX(FC_L,$I13))*(INDEX(FC_E1,$I13+1)-INDEX(FC_E1,$I13))/(INDEX(FC_L,$I13+1)-INDEX(FC_L,$I13)) -> 0.365 | K13: =INDEX(FC_E2,$I13)+(MEDIAN(MinStable,$F13,1)-INDEX(FC_L,$I13))*(INDEX(FC_E2,$I13+1)-INDEX(FC_E2,$I13))/(INDEX(FC_L,$I13+1)-INDEX(FC_L,$I13)) -> 0.36 | L13: =INDEX(FC_E3,$I13)+(MEDIAN(MinStable,$F13,1)-INDEX(FC_L,$I13))*(INDEX(FC_E3,$I13+1)-INDEX(FC_E3,$I13))/(INDEX(FC_L,$I13+1)-INDEX(FC_L,$I13)) -> 0.354 | M13: =(Cap_1*F13/J13+IF(N_base>=2,Cap_2*F13/K13,0)+IF(N_base>=3,Cap_3*F13/L13,0))*dt/60 -> 0.078754762
... A1441: 1439 | B1441: =A1441/1440 -> 0.99930556 | C1441: =Sim!C1441 -> 1.2226 | D1441: =Cap_base -> 3.4 | E1441: =MEDIAN(MinStable*D1441,C1441,D1441) -> 1.7 | F1441: =E1441/D1441 -> 0.5 | G1441: =MAX(0,C1441-E1441) -> 0 | H1441: =MAX(0,E1441-C1441) -> 0.4774 | I1441: =MIN(MATCH(MEDIAN(MinStable,F1441,1),FC_L,1),3) -> 2 | J1441: =INDEX(FC_E1,$I1441)+(MEDIAN(MinStable,$F1441,1)-INDEX(FC_L,$I1441))*(INDEX(FC_E1,$I1441+1)-INDEX(FC_E1,$I1441))/(INDEX(FC_L,$I1441+1)-INDEX(FC_L,$I1441)) -> 0.365 | K1441: =INDEX(FC_E2,$I1441)+(MEDIAN(MinStable,$F1441,1)-INDEX(FC_L,$I1441))*(INDEX(FC_E2,$I1441+1)-INDEX(FC_E2,$I1441))/(INDEX(FC_L,$I1441+1)-INDEX(FC_L,$I1441)) -> 0.36 | L1441: =INDEX(FC_E3,$I1441)+(MEDIAN(MinStable,$F1441,1)-INDEX(FC_L,$I1441))*(INDEX(FC_E3,$I1441+1)-INDEX(FC_E3,$I1441))/(INDEX(FC_L,$I1441+1)-INDEX(FC_L,$I1441)) -> 0.354 | M1441: =(Cap_1*F1441/J1441+IF(N_base>=2,Cap_2*F1441/K1441,0)+IF(N_base>=3,Cap_3*F1441/L1441,0))*dt/60 -> 0.078754762

Sheet Results
A1: Results — simulated 24 hours
A2: All figures recalculate from the Inputs sheet. Baseline = current operation. With BESS = rule-based dispatch.
B4: Baseline | C4: With BESS | D4: Difference
A5: ENERGY
A6: Process load served (MWh) | B6: =SUM(Baseline!C2:C1441)*dt/60 -> 62.32449 | C6: =SUM(Sim!C2:C1441)*dt/60 -> 62.32449 | D6: =C6-B6 -> 0 | E6: Identical by construction — same load series.
A7: CHP electrical output (MWh) | B7: =SUM(Baseline!E2:E1441)*dt/60 -> 63.591733 | C7: =SUM(Sim!AI2:AI1441)*dt/60 -> 63.279167 | D7: =C7-B7 -> -0.31256667
A8: Grid import (MWh) | B8: =SUM(Baseline!G2:G1441)*dt/60 -> 1.1679333 | C8: =SUM(Sim!AJ2:AJ1441)*dt/60 -> 0 | D8: =C8-B8 -> -1.1679333
A9: Curtailed / dumped generation (MWh) | B9: =SUM(Baseline!H2:H1441)*dt/60 -> 2.4351767 | C9: =0 -> 0 | D9: =C9-B9 -> -2.4351767 | E9: Baseline can over-generate at low load; the battery absorbs it instead.
A10: Gas consumed (MWh, LHV) | B10: =SUM(Baseline!M2:M1441) -> 158.34594 | C10: =SUM(Sim!AP2:AP1441) -> 149.92785 | D10: =C10-B10 -> -8.4180892
A11: Fleet average loading | B11: =AVERAGE(Baseline!F2:F1441) -> 0.77931046 | C11: =SUMPRODUCT(Sim!AK2:AK1441,--(Sim!AB2:AB1441>0))/MAX(1,SUMPRODUCT(--(Sim!AB2:AB1441>0))) -> 1 | D11: =C11-B11 -> 0.22068954 | E11: The core of the thesis — higher is better.
A13: ENGINES
A14: Unit 1 running hours | B14: =IF(N_base>=1,1440*dt/60,0) -> 24 | C14: =SUM(Sim!S2:S1441)*dt/60 -> 19.366667 | D14: =C14-B14 -> -4.6333333
A15: Unit 2 running hours | B15: =IF(N_base>=2,1440*dt/60,0) -> 24 | C15: =SUM(Sim!T2:T1441)*dt/60 -> 19.383333 | D15: =C15-B15 -> -4.6166667
A16: Unit 3 running hours | B16: =IF(N_base>=3,1440*dt/60,0) -> 24 | C16: =SUM(Sim!U2:U1441)*dt/60 -> 17.05 | D16: =C16-B16 -> -6.95
A17: Total fleet running hours | B17: =SUM(B14:B16) -> 72 | C17: =SUM(C14:C16) -> 55.8 | D17: =C17-B17 -> -16.2 | E17: Drives overhaul intervals and per-hour O&M.
A18: Engine starts | B18: =0 -> 0 | C18: =SUM(Sim!AR2:AR1441) -> 4 | D18: =C18-B18 -> 4 | E18: The counterweight to the hours saving.
A19: Start wear (equivalent run hours) | B19: =0 -> 0 | C19: =C18*StartEqH -> 60 | D19: =C19-B19 -> 60
A20: Effective hours (running + start wear) | B20: =B17+B19 -> 72 | C20: =C17+C19 -> 115.8 | D20: =C20-B20 -> 43.8 | E20: This is the number to use for maintenance economics.
A22: BATTERY
A23: Energy charged (MWh) | C23: =SUM(Sim!AG2:AG1441)*dt/60 -> 9.325565
A24: Energy discharged (MWh) | C24: =SUM(Sim!AH2:AH1441)*dt/60 -> 8.7308883
A25: Round-trip loss (MWh) | C25: =C23-C24 -> 0.59467667 | E25: Cost of buffering — the counterweight to the efficiency gain.
A26: Equivalent full cycles (day) | C26: =C24/E_nom -> 1.5874342 | E26: Annualise and check against the warranty.
A27: Equivalent full cycles (year) | C27: =C26*DaysYear -> 523.8533
A28: Minimum SOC reached | C28: =MIN(Sim!AQ2:AQ1441) -> 0.29734719 | E28: If this sits on the floor, the pack is undersized.
A29: Maximum SOC reached | C29: =MAX(Sim!AQ2:AQ1441) -> 0.85236482
A31: COST (simulated day)
A32: Gas cost (KZT) | B32: =B10*GasCost -> 750059.71 | C32: =C10*GasCost -> 710184.55 | D32: =C32-B32 -> -39875.16
A33: Grid import cost (KZT) | B33: =B8*GridCost -> 58396.667 | C33: =C8*GridCost -> 0 | D33: =C33-B33 -> -58396.667
A34: Engine O&M (KZT) | B34: =B20*OMhour -> 648000 | C34: =C20*OMhour -> 1042200 | D34: =C34-B34 -> 394200 | E34: ONLY real if their contract is per-operating-hour. Set the rate to zero if it is per-MWh.
A35: Total operating cost (KZT) | B35: =SUM(B32:B34) -> 1456456.4 | C35: =SUM(C32:C34) -> 1752384.6 | D35: =C35-B35 -> 295928.17
A37: ANNUALISED
A38: Saving per simulated day (KZT) | B38: =B35-C35 -> -295928.17 | E38: Positive = the BESS case is cheaper.
A39: Saving per year (KZT) | B39: =B38*DaysYear -> -97656297 | E39: Assumes the simulated day is representative — state this caveat explicitly to the client.
A40: Simple payback (years) | B40: =IF(B39<=0,"no payback",Capex/B39) -> no payback | E40: Undiscounted, before degradation and before any capacity-charge or reliability benefit.
A42: SCENARIO LOG — record results as you sweep the inputs
A43: Scenario name | B43: SOC start | C43: SOC stop | D43: Start margin (MW) | E43: BESS MWh | F43: BESS MW | G43: Gas (MWh) | H43: Fleet hours | I43: Starts | J43: Import (MWh) | K43: EFC/yr | L43: Saving/yr (KZT)
A44: Aggressive (start margin = PCS) | B44: 0.3 | C44: 0.85 | D44: 2.5 | E44: 5.5 | F44: 2.5
A53: Row 44 shows the format. Change the Inputs, read the numbers above, and paste them in as values.

Sheet Chart
A1: Simulated day — load, CHP output and SOC
A2: Sampled every 5 minutes for legibility. The underlying model runs at 1 minute.
A4: Time | B4: Process load (MW) | C4: CHP output (MW) | D4: Grid import (MW) | E4: SOC (%) | F4: Units running | G4: BESS discharge (MW)
A5: =Sim!B2 -> 0 | B5: =Sim!C2 -> 1.172 | C5: =Sim!AI2 -> 2.3 | D5: =Sim!AJ2 -> 0 | E5: =Sim!AQ2*100 -> 60.31639 | F5: =Sim!S2+Sim!T2+Sim!U2 -> 2 | G5: =Sim!AH2 -> 0
A6: =Sim!B7 -> 0.0034722222 | B6: =Sim!C7 -> 1.2374 | C6: =Sim!AI7 -> 2.3 | D6: =Sim!AJ7 -> 0 | E6: =Sim!AQ7*100 -> 61.916987 | F6: =Sim!S7+Sim!T7+Sim!U7 -> 2 | G6: =Sim!AH7 -> 0
A7: =Sim!B12 -> 0.0069444444 | B7: =Sim!C12 -> 1.1619 | C7: =Sim!AI12 -> 2.3 | D7: =Sim!AJ12 -> 0 | E7: =Sim!AQ12*100 -> 63.496094 | F7: =Sim!S12+Sim!T12+Sim!U12 -> 2 | G7: =Sim!AH12 -> 0
A8: =Sim!B17 -> 0.010416667 | B8: =Sim!C17 -> 1.1328 | C8: =Sim!AI17 -> 2.3 | D8: =Sim!AJ17 -> 0 | E8: =Sim!AQ17*100 -> 65.080431 | F8: =Sim!S17+Sim!T17+Sim!U17 -> 2 | G8: =Sim!AH17 -> 0
A9: =Sim!B22 -> 0.013888889 | B9: =Sim!C22 -> 1.1122 | C9: =Sim!AI22 -> 2.3 | D9: =Sim!AJ22 -> 0 | E9: =Sim!AQ22*100 -> 66.702206 | F9: =Sim!S22+Sim!T22+Sim!U22 -> 2 | G9: =Sim!AH22 -> 0
A10: =Sim!B27 -> 0.017361111 | B10: =Sim!C27 -> 1.0801 | C10: =Sim!AI27 -> 2.3 | D10: =Sim!AJ27 -> 0 | E10: =Sim!AQ27*100 -> 68.376969 | F10: =Sim!S27+Sim!T27+Sim!U27 -> 2 | G10: =Sim!AH27 -> 0
A11: =Sim!B32 -> 0.020833333 | B11: =Sim!C32 -> 1.1537 | C11: =Sim!AI32 -> 2.3 | D11: =Sim!AJ32 -> 0 | E11: =Sim!AQ32*100 -> 69.960482 | F11: =Sim!S32+Sim!T32+Sim!U32 -> 2 | G11: =Sim!AH32 -> 0
A12: =Sim!B37 -> 0.024305556 | B12: =Sim!C37 -> 1.2343 | C12: =Sim!AI37 -> 2.3 | D12: =Sim!AJ37 -> 0 | E12: =Sim!AQ37*100 -> 71.529355 | F12: =Sim!S37+Sim!T37+Sim!U37 -> 2 | G12: =Sim!AH37 -> 0
A13: =Sim!B42 -> 0.027777778 | B13: =Sim!C42 -> 1.2262 | C13: =Sim!AI42 -> 2.3 | D13: =Sim!AJ42 -> 0 | E13: =Sim!AQ42*100 -> 73.149367 | F13: =Sim!S42+Sim!T42+Sim!U42 -> 2 | G13: =Sim!AH42 -> 0
A14: =Sim!B47 -> 0.03125 | B14: =Sim!C47 -> 1.158 | C14: =Sim!AI47 -> 2.3 | D14: =Sim!AJ47 -> 0 | E14: =Sim!AQ47*100 -> 74.742318 | F14: =Sim!S47+Sim!T47+Sim!U47 -> 2 | G14: =Sim!AH47 -> 0
A15: =Sim!B52 -> 0.034722222 | B15: =Sim!C52 -> 1.1568 | C15: =Sim!AI52 -> 2.3 | D15: =Sim!AJ52 -> 0 | E15: =Sim!AQ52*100 -> 76.316222 | F15: =Sim!S52+Sim!T52+Sim!U52 -> 2 | G15: =Sim!AH52 -> 0
A16: =Sim!B57 -> 0.038194444 | B16: =Sim!C57 -> 1.0586 | C16: =Sim!AI57 -> 2.3 | D16: =Sim!AJ57 -> 0 | E16: =Sim!AQ57*100 -> 77.962587 | F16: =Sim!S57+Sim!T57+Sim!U57 -> 2 | G16: =Sim!AH57 -> 0
A17: =Sim!B62 -> 0.041666667 | B17: =Sim!C62 -> 1.1567 | C17: =Sim!AI62 -> 2.3 | D17: =Sim!AJ62 -> 0 | E17: =Sim!AQ62*100 -> 79.572423 | F17: =Sim!S62+Sim!T62+Sim!U62 -> 2 | G17: =Sim!AH62 -> 0
A18: =Sim!B67 -> 0.045138889 | B18: =Sim!C67 -> 1.1546 | C18: =Sim!AI67 -> 2.3 | D18: =Sim!AJ67 -> 0 | E18: =Sim!AQ67*100 -> 80.890714 | F18: =Sim!S67+Sim!T67+Sim!U67 -> 2 | G18: =Sim!AH67 -> 0
A19: =Sim!B72 -> 0.048611111 | B19: =Sim!C72 -> 1.1674 | C19: =Sim!AI72 -> 2.3 | D19: =Sim!AJ72 -> 0 | E19: =Sim!AQ72*100 -> 82.492704 | F19: =Sim!S72+Sim!T72+Sim!U72 -> 2 | G19: =Sim!AH72 -> 0
A20: =Sim!B77 -> 0.052083333 | B20: =Sim!C77 -> 1.1973 | C20: =Sim!AI77 -> 2.3 | D20: =Sim!AJ77 -> 0 | E20: =Sim!AQ77*100 -> 84.119113 | F20: =Sim!S77+Sim!T77+Sim!U77 -> 2 | G20: =Sim!AH77 -> 0
A21: =Sim!B82 -> 0.055555556 | B21: =Sim!C82 -> 1.7516 | C21: =Sim!AI82 -> 0 | D21: =Sim!AJ82 -> 0 | E21: =Sim!AQ82*100 -> 84.512637 | F21: =Sim!S82+Sim!T82+Sim!U82 -> 0 | G21: =Sim!AH82 -> 1.7666
A22: =Sim!B87 -> 0.059027778 | B22: =Sim!C87 -> 1.1076 | C22: =Sim!AI87 -> 0 | D22: =Sim!AJ87 -> 0 | E22: =Sim!AQ87*100 -> 82.300228 | F22: =Sim!S87+Sim!T87+Sim!U87 -> 0 | G22: =Sim!AH87 -> 1.1226
